Workbook
Name beta_observed: #REF!
Name beta_unlev_comps: #REF!
Name conversionfactor: '[10]E&P'!$D$6
Name convfactor: #REF!
Name costdebtfirm: #REF!
Name costequity: #REF!
Name days_per_year: #REF!
Name debt: #REF!
Name debt_weight: #REF!
Name market_equity: #REF!
Name relevered_beta: #REF!
Name risk_free_rate: #REF!
Name risk_premium: #REF!
Name stubyear: #REF!
Name totalcap: #REF!
Name wacc: #REF!

Sheet Transaction Summary
B2: Transaction Summary | D2: Brooks Phillips
B4: Sources & Uses
D5: CLOSE | H5: HOLD
D6: Total | E6: % of Total | F6: Per Unit | H6: Total | I6: % of Total | J6: Per Unit
B7: Uses
B8: Purchase Price | D8: =Model!E95 -> 51000000 | E8: =D8/$D$12 -> 0.98425197 | F8: =D8/$J$23 -> 204000 | H8: =Model!F95 -> 51000000 | I8: =H8/$H$12 -> 0.95054377 | J8: =H8/$J$23 -> 204000
B9: Closing Costs | D9: =Model!E96 -> 637500 | E9: =D9/$D$12 -> 0.01230315 | F9: =D9/$J$23 -> 2550 | H9: =Model!F96 -> 637500 | I9: =H9/$H$12 -> 0.011881797 | J9: =H9/$J$23 -> 2550
B10: Capital Expenditures | D10: =Model!E97 -> 0 | E10: =D10/$D$12 -> 0 | F10: =D10/$J$23 -> 0 | H10: =Model!F97 -> 1837500 | I10: =H10/$H$12 -> 0.034247533 | J10: =H10/$J$23 -> 7350
B11: Financing Fees | D11: =Model!E98 -> 178500 | E11: =D11/$D$12 -> 0.0034448819 | F11: =D11/$J$23 -> 714 | H11: =Model!F98 -> 178500 | I11: =H11/$H$12 -> 0.0033269032 | J11: =H11/$J$23 -> 714
B12: Total Uses | D12: =SUM(D8:D11) -> 51816000 | E12: =SUM(E8:E11) -> 1 | F12: =SUM(F8:F11) -> 207264 | H12: =SUM(H8:H11) -> 53653500 | I12: =SUM(I8:I11) -> 1 | J12: =SUM(J8:J11) -> 214614
B14: Sources
B15: Equity | D15: =Model!E102 -> 16116000 | E15: =D15/$D$18 -> 0.31102362 | F15: =D15/$J$23 -> 64464 | H15: =Model!F102 -> 16204471 | I15: =H15/$H$18 -> 0.30202076 | J15: =H15/$J$23 -> 64817.884
B16: Debt | D16: =Model!E103 -> 35700000 | E16: =D16/$D$18 -> 0.68897638 | F16: =D16/$J$23 -> 142800 | H16: =Model!F103 -> 35700000 | I16: =H16/$H$18 -> 0.66538064 | J16: =H16/$J$23 -> 142800
B17: Operating Cashflow | D17: =Model!E104 -> 0 | E17: =D17/$D$18 -> 0 | F17: =D17/$J$23 -> 0 | H17: =Model!F104 -> 1749029 | I17: =H17/$H$18 -> 0.0325986 | J17: =H17/$J$23 -> 6996.116
B18: Total Sources | D18: =SUM(D15:D17) -> 51816000 | E18: =SUM(E15:E17) -> 1 | F18: =SUM(F15:F17) -> 207264 | H18: =SUM(H15:H17) -> 53653500 | I18: =SUM(I15:I17) -> 1 | J18: =SUM(J15:J17) -> 214614
B20: Returns Summary | H20: Property Overview
C21: Peak Equity | D21: IRR | E21: Profit | F21: Multiple | H21: Location | J21: ='Inputs & Drivers'!E7 -> 123 Wall Street, Boston, MA
B22: Unlevered Project | C22: {=TRANSPOSE(Model!C65:C68)} -> 51637500 | D22: 0.091856948 | E22: 25486681 | F22: 1.4935692 | H22: Vintage | J22: ='Inputs & Drivers'!E9 -> 2010
B23: Levered Project | C23: {=TRANSPOSE(Model!C88:C91)} -> 16204471 | D23: 0.1709843 | E23: 17412446 | F23: 2.0745458 | H23: Total Units | J23: ='Inputs & Drivers'!E8 -> 250
H24: Hold Period | J24: ='Inputs & Drivers'!E13 -> 60
H25: Rentable SF | J25: ='Inputs & Drivers'!I10*'Inputs & Drivers'!J10 -> 230000
H26: Avg Unit Size | J26: =J25/J23 -> 920
H27: Current Occ. | J27: ='Inputs & Drivers'!E35 -> 0.9
B29: NOI Summary | H29: Unit Mix
C30: NOI | D30: Growth | E30: NOI YoC | F30: Delta to Exit Cap | H30: Type | I30: Count | J30: %
B31: 1 | C31: {=TRANSPOSE(Model!EN44:ES44)} -> 2738296.4 | E31: =C31/$H$18 -> 0.051036679 | F31: =E31-$D$48 -> -0.0064633214 | H31: ='Inputs & Drivers'!G6 -> Studio | I31: ='Inputs & Drivers'!J6 -> 20 | J31: =I31/$I$35 -> 0.08
B32: =++B31+1 -> 2 | C32: 2989929.7 | D32: =C32/C31-1 -> 0.091894097 | E32: =C32/$H$18 -> 0.055726648 | F32: =E32-$D$48 -> -0.0017733519 | H32: ='Inputs & Drivers'!G7 -> 1 BR, 1 BA | I32: ='Inputs & Drivers'!J7 -> 140 | J32: =I32/$I$35 -> 0.56
B33: =++B32+1 -> 3 | C33: 3294209 | D33: =C33/C32-1 -> 0.10176802 | E33: =C33/$H$18 -> 0.061397839 | F33: =E33-$D$48 -> 0.0038978389 | H33: ='Inputs & Drivers'!G8 -> 2 BR, 2 BA | I33: ='Inputs & Drivers'!J8 -> 80 | J33: =I33/$I$35 -> 0.32
B34: =++B33+1 -> 4 | C34: 3432779.7 | D34: =C34/C33-1 -> 0.042064956 | E34: =C34/$H$18 -> 0.063980536 | F34: =E34-$D$48 -> 0.0064805364 | H34: ='Inputs & Drivers'!G9 -> 3 BR, 2 BA | I34: ='Inputs & Drivers'!J9 -> 10 | J34: =I34/$I$35 -> 0.04
B35: =++B34+1 -> 5 | C35: 3547442.2 | D35: =C35/C34-1 -> 0.033402221 | E35: =C35/$H$18 -> 0.066117628 | F35: =E35-$D$48 -> 0.0086176284 | H35: Total | I35: =SUM(I31:I34) -> 250 | J35: =I35/$I$35 -> 1
B36: =++B35+1 -> 6 | C36: 3665968.5 | D36: =C36/C35-1 -> 0.033411763 | E36: =C36/$H$18 -> 0.068326735 | F36: =E36-$D$48 -> 0.010826735
B38: Capital Expenditure Summary | H38: Debt Summary
E39: Per Unit | F39: Total | H39: Loan Proceeds | J39: ='Inputs & Drivers'!J22 -> 35700000
B40: Deferred Maintenance | E40: =F40/$J$23 -> 1050 | F40: ='Inputs & Drivers'!E22 -> 262500 | H40: Leverage (Close / Life) | J40: =TEXT(D16/D18,"0%")&" / "&TEXT(H16/H18,"0%") -> 69% / 67%
B41: Offensive Renovations | E41: =F41/$J$23 -> 6300 | F41: ='Inputs & Drivers'!E27 -> 1575000 | H41: Rate | J41: ='Inputs & Drivers'!J25 -> 0.0466275
B42: Subtotal | E42: =F42/$J$23 -> 7350 | F42: =SUM(F40:F41) -> 1837500 | H42: Fees | J42: ='Inputs & Drivers'!J28 -> 0.005
B43: Replacement Reserves | E43: =F43/J23 -> 1250 | F43: =-SUMIF(Model!$I$6:$EK$6,"<="&Model!$C$5,Model!I41:EK41) -> 312500 | H43: IO Period | J43: ='Inputs & Drivers'!J26 -> 48
B44: Total | E44: =F44/$J$23 -> 8600 | F44: =SUM(F42:F43) -> 2150000 | H44: Maturity | J44: ='Inputs & Drivers'!J21 -> 45291
B46: Exit Summary | H46: Unit Renovation ROI
C47: Fwd NOI | D47: Exit Cap | E47: Total $ | F47: Per Unit | H47: Units Renovated | I47: =J47/J23 -> 1 | J47: ='Inputs & Drivers'!E72 -> 250
...

Sheet Inputs & Drivers
B2: Inputs | D2: Brooks Phillips | M2: LIBOR Index | Q2: Amortization Table
B4: Property Overview | G4: Unit Mix | M4: Date | N4: LIBOR | Q4: Date | R4: # | S4: Payment | T4: Beg. Balance | U4: Principal | V4: Interest | W4: End Balance
B5: Name | E5: Rock Creek Apartments | G5: Type | I5: Size | J5: Count | M5: 43465 | N5: 0.0251275 | Q5: =J19 -> 43465 | R5: 0 | S5: =-PMT($J$25/12,$J$27*12,$J$22) -> 184355.25 | T5: =J22 -> 35700000 | U5: =(S5-V5)*(R5>$J$26) -> 0 | V5: 0 | W5: =T5-U5 -> 35700000
B6: Type | E6: Multifamily | G6: Studio | I6: 500 | J6: 20 | M6: 43503 | N6: 0.0250547 | Q6: =EOMONTH(Q5,1) -> 43496 | R6: =++R5+1 -> 1 | S6: =S5 -> 184355.25 | T6: =W5 -> 35700000 | U6: =(S6-V6)*(R6>$J$26) -> 0 | V6: =$J$25*T6*((Q6-Q5)/365) -> 141377.13 | W6: =T6-U6 -> 35700000
B7: Location | E7: 123 Wall Street, Boston, MA | G7: 1 BR, 1 BA | I7: 750 | J7: 140 | M7: 43531 | N7: 0.0249624 | Q7: =EOMONTH(Q6,1) -> 43524 | R7: =++R6+1 -> 2 | S7: =S6 -> 184355.25 | T7: =W6 -> 35700000 | U7: =(S7-V7)*(R7>$J$26) -> 0 | V7: =$J$25*T7*((Q7-Q6)/365) -> 127695.48 | W7: =T7-U7 -> 35700000
B8: Units | E8: 250 | G8: 2 BR, 2 BA | I8: 1250 | J8: 80 | M8: 43563 | N8: 0.0249459 | Q8: =EOMONTH(Q7,1) -> 43555 | R8: =++R7+1 -> 3 | S8: =S7 -> 184355.25 | T8: =W7 -> 35700000 | U8: =(S8-V8)*(R8>$J$26) -> 0 | V8: =$J$25*T8*((Q8-Q7)/365) -> 141377.13 | W8: =T8-U8 -> 35700000
B9: Year Built | E9: 2010 | G9: 3 BR, 2 BA | I9: 1500 | J9: 10 | M9: 43592 | N9: 0.024956 | Q9: =EOMONTH(Q8,1) -> 43585 | R9: =++R8+1 -> 4 | S9: =S8 -> 184355.25 | T9: =W8 -> 35700000 | U9: =(S9-V9)*(R9>$J$26) -> 0 | V9: =$J$25*T9*((Q9-Q8)/365) -> 136816.58 | W9: =T9-U9 -> 35700000
G10: Total | I10: =SUMPRODUCT(I6:I9,J6:J9)/J10 -> 920 | J10: =SUM(J6:J9) -> 250 | M10: 43623 | N10: 0.0249169 | Q10: =EOMONTH(Q9,1) -> 43616 | R10: =++R9+1 -> 5 | S10: =S9 -> 184355.25 | T10: =W9 -> 35700000 | U10: =(S10-V10)*(R10>$J$26) -> 0 | V10: =$J$25*T10*((Q10-Q9)/365) -> 141377.13 | W10: =T10-U10 -> 35700000
B11: Acquisition Assumptions | M11: 43654 | N11: 0.0248534 | Q11: =EOMONTH(Q10,1) -> 43646 | R11: =++R10+1 -> 6 | S11: =S10 -> 184355.25 | T11: =W10 -> 35700000 | U11: =(S11-V11)*(R11>$J$26) -> 0 | V11: =$J$25*T11*((Q11-Q10)/365) -> 136816.58 | W11: =T11-U11 -> 35700000
B12: Acquisition Date | E12: 43465 | G12: Exit Assumptions | M12: 43684 | N12: 0.0247617 | Q12: =EOMONTH(Q11,1) -> 43677 | R12: =++R11+1 -> 7 | S12: =S11 -> 184355.25 | T12: =W11 -> 35700000 | U12: =(S12-V12)*(R12>$J$26) -> 0 | V12: =$J$25*T12*((Q12-Q11)/365) -> 141377.13 | W12: =T12-U12 -> 35700000
B13: Hold Period | E13: 60 | G13: Exit Date | J13: =EOMONTH(E12,E13) -> 45291 | M13: 43717 | N13: 0.0246092 | Q13: =EOMONTH(Q12,1) -> 43708 | R13: =++R12+1 -> 8 | S13: =S12 -> 184355.25 | T13: =W12 -> 35700000 | U13: =(S13-V13)*(R13>$J$26) -> 0 | V13: =$J$25*T13*((Q13-Q12)/365) -> 141377.13 | W13: =T13-U13 -> 35700000
B14: Purchase Price | E14: 51000000 | G14: Exit Cap Rate | J14: 0.0575 | M14: 43745 | N14: 0.0244316 | Q14: =EOMONTH(Q13,1) -> 43738 | R14: =++R13+1 -> 9 | S14: =S13 -> 184355.25 | T14: =W13 -> 35700000 | U14: =(S14-V14)*(R14>$J$26) -> 0 | V14: =$J$25*T14*((Q14-Q13)/365) -> 136816.58 | W14: =T14-U14 -> 35700000
B15: Acquisition Closing Costs | E15: 0.0125 | G15: Sale Price | J15: =SUM(Model!I59:EK59) -> 63755973 | M15: 43776 | N15: 0.0242373 | Q15: =EOMONTH(Q14,1) -> 43769 | R15: =++R14+1 -> 10 | S15: =S14 -> 184355.25 | T15: =W14 -> 35700000 | U15: =(S15-V15)*(R15>$J$26) -> 0 | V15: =$J$25*T15*((Q15-Q14)/365) -> 141377.13 | W15: =T15-U15 -> 35700000
G16: Exit Closing Costs | J16: 0.0125 | M16: 43808 | N16: 0.0239998 | Q16: =EOMONTH(Q15,1) -> 43799 | R16: =++R15+1 -> 11 | S16: =S15 -> 184355.25 | T16: =W15 -> 35700000 | U16: =(S16-V16)*(R16>$J$26) -> 0 | V16: =$J$25*T16*((Q16-Q15)/365) -> 136816.58 | W16: =T16-U16 -> 35700000
B17: Renovation Budget | M17: 43837 | N17: 0.0237498 | Q17: =EOMONTH(Q16,1) -> 43830 | R17: =++R16+1 -> 12 | S17: =S16 -> 184355.25 | T17: =W16 -> 35700000 | U17: =(S17-V17)*(R17>$J$26) -> 0 | V17: =$J$25*T17*((Q17-Q16)/365) -> 141377.13 | W17: =T17-U17 -> 35700000
D18: Per Unit | E18: Total | G18: Financing Assumptions | M18: 43868 | N18: 0.0234851 | Q18: =EOMONTH(Q17,1) -> 43861 | R18: =++R17+1 -> 13 | S18: =S17 -> 184355.25 | T18: =W17 -> 35700000 | U18: =(S18-V18)*(R18>$J$26) -> 0 | V18: =$J$25*T18*((Q18-Q17)/365) -> 141377.13 | W18: =T18-U18 -> 35700000
B19: Defensive | G19: Start Date | J19: =E12 -> 43465 | M19: 43899 | N19: 0.0231708 | Q19: =EOMONTH(Q18,1) -> 43890 | R19: =++R18+1 -> 14 | S19: =S18 -> 184355.25 | T19: =W18 -> 35700000 | U19: =(S19-V19)*(R19>$J$26) -> 0 | V19: =$J$25*T19*((Q19-Q18)/365) -> 132256.03 | W19: =T19-U19 -> 35700000
B20: Amount | D20: =E20/$E$8 -> 1000 | E20: 250000 | G20: Term | J20: =E13 -> 60 | M20: 43928 | N20: 0.0228538 | Q20: =EOMONTH(Q19,1) -> 43921 | R20: =++R19+1 -> 15 | S20: =S19 -> 184355.25 | T20: =W19 -> 35700000 | U20: =(S20-V20)*(R20>$J$26) -> 0 | V20: =$J$25*T20*((Q20-Q19)/365) -> 141377.13 | W20: =T20-U20 -> 35700000
B21: Contingency | D21: 0.05 | E21: =D21*E20 -> 12500 | G21: Maturity Date | J21: =EOMONTH(J19,J20) -> 45291 | M21: 43958 | N21: 0.0225506 | Q21: =EOMONTH(Q20,1) -> 43951 | R21: =++R20+1 -> 16 | S21: =S20 -> 184355.25 | T21: =W20 -> 35700000 | U21: =(S21-V21)*(R21>$J$26) -> 0 | V21: =$J$25*T21*((Q21-Q20)/365) -> 136816.58 | W21: =T21-U21 -> 35700000
B22: Subtotal | E22: =SUM(E20:E21) -> 262500 | G22: Loan Amount | J22: =J23*E14 -> 35700000 | M22: 43990 | N22: 0.0222459 | Q22: =EOMONTH(Q21,1) -> 43982 | R22: =++R21+1 -> 17 | S22: =S21 -> 184355.25 | T22: =W21 -> 35700000 | U22: =(S22-V22)*(R22>$J$26) -> 0 | V22: =$J$25*T22*((Q22-Q21)/365) -> 141377.13 | W22: =T22-U22 -> 35700000
G23: Loan-to-Purchase Price | J23: 0.7 | M23: 44019 | N23: 0.0219826 | Q23: =EOMONTH(Q22,1) -> 44012 | R23: =++R22+1 -> 18 | S23: =S22 -> 184355.25 | T23: =W22 -> 35700000 | U23: =(S23-V23)*(R23>$J$26) -> 0 | V23: =$J$25*T23*((Q23-Q22)/365) -> 136816.58 | W23: =T23-U23 -> 35700000
B24: Offensive | G24: Interest Rate Spread | J24: 215 | M24: 44050 | N24: 0.021773 | Q24: =EOMONTH(Q23,1) -> 44043 | R24: =++R23+1 -> 19 | S24: =S23 -> 184355.25 | T24: =W23 -> 35700000 | U24: =(S24-V24)*(R24>$J$26) -> 0 | V24: =$J$25*T24*((Q24-Q23)/365) -> 141377.13 | W24: =T24-U24 -> 35700000
B25: Amount | D25: 6000 | E25: =D25*$E$8 -> 1500000 | G25: All-in Rate | J25: =N5+J24/10000 -> 0.0466275 | M25: 44081 | N25: 0.0215892 | Q25: =EOMONTH(Q24,1) -> 44074 | R25: =++R24+1 -> 20 | S25: =S24 -> 184355.25 | T25: =W24 -> 35700000 | U25: =(S25-V25)*(R25>$J$26) -> 0 | V25: =$J$25*T25*((Q25-Q24)/365) -> 141377.13 | W25: =T25-U25 -> 35700000
B26: Contingency | D26: 0.05 | E26: =D26*E25 -> 75000 | G26: Interest Only Period | J26: 48 | M26: 44111 | N26: 0.0214692 | Q26: =EOMONTH(Q25,1) -> 44104 | R26: =++R25+1 -> 21 | S26: =S25 -> 184355.25 | T26: =W25 -> 35700000 | U26: =(S26-V26)*(R26>$J$26) -> 0 | V26: =$J$25*T26*((Q26-Q25)/365) -> 136816.58 | W26: =T26-U26 -> 35700000
B27: Subtotal | E27: =SUM(E25:E26) -> 1575000 | G27: Amortization Period | J27: 30 | M27: 44144 | N27: 0.0214124 | Q27: =EOMONTH(Q26,1) -> 44135 | R27: =++R26+1 -> 22 | S27: =S26 -> 184355.25 | T27: =W26 -> 35700000 | U27: =(S27-V27)*(R27>$J$26) -> 0 | V27: =$J$25*T27*((Q27-Q26)/365) -> 141377.13 | W27: =T27-U27 -> 35700000
B28: Total | E28: =E22+E27 -> 1837500 | G28: Origination Fee | J28: 0.005 | M28: 44172 | N28: 0.0213752 | Q28: =EOMONTH(Q27,1) -> 44165 | R28: =++R27+1 -> 23 | S28: =S27 -> 184355.25 | T28: =W27 -> 35700000 | U28: =(S28-V28)*(R28>$J$26) -> 0 | V28: =$J$25*T28*((Q28-Q27)/365) -> 136816.58 | W28: =T28-U28 -> 35700000
M29: 44203 | N29: 0.0213804 | Q29: =EOMONTH(Q28,1) -> 44196 | R29: =++R28+1 -> 24 | S29: =S28 -> 184355.25 | T29: =W28 -> 35700000 | U29: =(S29-V29)*(R29>$J$26) -> 0 | V29: =$J$25*T29*((Q29-Q28)/365) -> 141377.13 | W29: =T29-U29 -> 35700000
M30: 44235 | N30: 0.0214102 | Q30: =EOMONTH(Q29,1) -> 44227 | R30: =++R29+1 -> 25 | S30: =S29 -> 184355.25 | T30: =W29 -> 35700000 | U30: =(S30-V30)*(R30>$J$26) -> 0 | V30: =$J$25*T30*((Q30-Q29)/365) -> 141377.13 | W30: =T30-U30 -> 35700000
B31: Drivers | M31: 44263 | N31: 0.0214238 | Q31: =EOMONTH(Q30,1) -> 44255 | R31: =++R30+1 -> 26 | S31: =S30 -> 184355.25 | T31: =W30 -> 35700000 | U31: =(S31-V31)*(R31>$J$26) -> 0 | V31: =$J$25*T31*((Q31-Q30)/365) -> 127695.48 | W31: =T31-U31 -> 35700000
M32: 44293 | N32: 0.0214432 | Q32: =EOMONTH(Q31,1) -> 44286 | R32: =++R31+1 -> 27 | S32: =S31 -> 184355.25 | T32: =W31 -> 35700000 | U32: =(S32-V32)*(R32>$J$26) -> 0 | V32: =$J$25*T32*((Q32-Q31)/365) -> 141377.13 | W32: =T32-U32 -> 35700000
B33: Income Assumptions | G33: Operating Expense Assumptions | M33: 44323 | N33: 0.0214684 | Q33: =EOMONTH(Q32,1) -> 44316 | R33: =++R32+1 -> 28 | S33: =S32 -> 184355.25 | T33: =W32 -> 35700000 | U33: =(S33-V33)*(R33>$J$26) -> 0 | V33: =$J$25*T33*((Q33-Q32)/365) -> 136816.58 | W33: =T33-U33 -> 35700000
D34: Assumption | E34: Total | H34: % | I34: Per Unit | J34: Total | M34: 44354 | N34: 0.0214777 | Q34: =EOMONTH(Q33,1) -> 44347 | R34: =++R33+1 -> 29 | S34: =S33 -> 184355.25 | T34: =W33 -> 35700000 | U34: =(S34-V34)*(R34>$J$26) -> 0 | V34: =$J$25*T34*((Q34-Q33)/365) -> 141377.13 | W34: =T34-U34 -> 35700000
B35: Occupancy | E35: =Model!F22 -> 0.9 | G35: Repairs & Maintenance | I35: =Model!G32 -> 1327.92 | J35: =I35*$E$8 -> 331980 | M35: 44384 | N35: 0.0214958 | Q35: =EOMONTH(Q34,1) -> 44377 | R35: =++R34+1 -> 30 | S35: =S34 -> 184355.25 | T35: =W34 -> 35700000 | U35: =(S35-V35)*(R35>$J$26) -> 0 | V35: =$J$25*T35*((Q35-Q34)/365) -> 136816.58 | W35: =T35-U35 -> 35700000
B36: Effective Rent / Month | E36: =Model!F20 -> 2053.8001 | G36: Turnover | I36: =Model!G33 -> 351.648 | J36: =I36*$E$8 -> 87912 | M36: 44417 | N36: 0.0215259 | Q36: =EOMONTH(Q35,1) -> 44408 | R36: =++R35+1 -> 31 | S36: =S35 -> 184355.25 | T36: =W35 -> 35700000 | U36: =(S36-V36)*(R36>$J$26) -> 0 | V36: =$J$25*T36*((Q36-Q35)/365) -> 141377.13 | W36: =T36-U36 -> 35700000
G37: Marketing | I37: =Model!G34 -> 1158.512 | J37: =I37*$E$8 -> 289628 | M37: 44446 | N37: 0.021547 | Q37: =EOMONTH(Q36,1) -> 44439 | R37: =++R36+1 -> 32 | S37: =S36 -> 184355.25 | T37: =W36 -> 35700000 | U37: =(S37-V37)*(R37>$J$26) -> 0 | V37: =$J$25*T37*((Q37-Q36)/365) -> 141377.13 | W37: =T37-U37 -> 35700000
B38: Effective Rent | E38: =E36*E8*12 -> 6161400.4 | G38: General & Administrative | I38: =Model!G35 -> 280.544 | J38: =I38*$E$8 -> 70136 | M38: 44476 | N38: 0.0215818 | Q38: =EOMONTH(Q37,1) -> 44469 | R38: =++R37+1 -> 33 | S38: =S37 -> 184355.25 | T38: =W37 -> 35700000 | U38: =(S38-V38)*(R38>$J$26) -> 0 | V38: =$J$25*T38*((Q38-Q37)/365) -> 136816.58 | W38: =T38-U38 -> 35700000
B39: Vacancy Loss | E39: =Model!F16 -> -616140.04 | G39: Payroll | I39: =Model!G36 -> 1519.568 | J39: =I39*$E$8 -> 379892 | M39: 44508 | N39: 0.0216311 | Q39: =EOMONTH(Q38,1) -> 44500 | R39: =++R38+1 -> 34 | S39: =S38 -> 184355.25 | T39: =W38 -> 35700000 | U39: =(S39-V39)*(R39>$J$26) -> 0 | V39: =$J$25*T39*((Q39-Q38)/365) -> 141377.13 | W39: =T39-U39 -> 35700000
B40: Non-Revenue Units | D40: =-E40/$E$38 -> 0.0017138961 | E40: =Model!F17 -> -10560 | G40: Management Fees | H40: 0.029772407 | I40: =J40/E8 -> 656.22057 | J40: =H40*E42 -> 164055.14 | M40: 44537 | N40: 0.0216726 | Q40: =EOMONTH(Q39,1) -> 44530 | R40: =++R39+1 -> 35 | S40: =S39 -> 184355.25 | T40: =W39 -> 35700000 | U40: =(S40-V40)*(R40>$J$26) -> 0 | V40: =$J$25*T40*((Q40-Q39)/365) -> 136816.58 | W40: =T40-U40 -> 35700000
B41: Collection Loss | D41: =-E41/$E$38 -> 0.0039588403 | E41: =Model!F18 -> -24392 | G41: Utilities | I41: =Model!G38 -> 582.272 | J41: =I41*$E$8 -> 145568 | M41: 44568 | N41: 0.0217284 | Q41: =EOMONTH(Q40,1) -> 44561 | R41: =++R40+1 -> 36 | S41: =S40 -> 184355.25 | T41: =W40 -> 35700000 | U41: =(S41-V41)*(R41>$J$26) -> 0 | V41: =$J$25*T41*((Q41-Q40)/365) -> 141377.13 | W41: =T41-U41 -> 35700000
B42: Total Rental Income | E42: =SUM(E38:E41) -> 5510308.4 | G42: Real Estate Taxes | I42: =Model!G39 -> 6554.016 | J42: =I42*$E$8 -> 1638504 | M42: 44599 | N42: 0.0217982 | Q42: =EOMONTH(Q41,1) -> 44592 | R42: =++R41+1 -> 37 | S42: =S41 -> 184355.25 | T42: =W41 -> 35700000 | U42: =(S42-V42)*(R42>$J$26) -> 0 | V42: =$J$25*T42*((Q42-Q41)/365) -> 141377.13 | W42: =T42-U42 -> 35700000
...

Sheet Model
B2: Model
B4: Acq. Date | C4: ='Inputs & Drivers'!E12 -> 43465 | E4: Dec 2018 | F4: Dec 2018 | I4: 0 | J4: 1 | K4: 1 | L4: 1 | M4: 1 | N4: 1 | O4: 1 | P4: 1 | Q4: 1 | R4: 1 | S4: 1 | T4: 1 | U4: 1 | V4: =J4+1 -> 2 | W4: =K4+1 -> 2 | X4: =L4+1 -> 2 | Y4: =M4+1 -> 2 | Z4: =N4+1 -> 2 | AA4: =O4+1 -> 2 | AB4: =P4+1 -> 2 | AC4: =Q4+1 -> 2 | ... EK4: =DY4+1 -> 11
B5: Exit Date | C5: ='Inputs & Drivers'!J13 -> 45291 | E5: T-3 Ann. | F5: T-12 | I5: 0 | J5: =++I5+1 -> 1 | K5: =++J5+1 -> 2 | L5: =++K5+1 -> 3 | M5: =++L5+1 -> 4 | N5: =++M5+1 -> 5 | O5: =++N5+1 -> 6 | P5: =++O5+1 -> 7 | Q5: =++P5+1 -> 8 | ... EK5: =++EJ5+1 -> 132 | EM5: 0 | EN5: =EM5+1 -> 1 | EO5: =EN5+1 -> 2 | EP5: =EO5+1 -> 3 | EQ5: =EP5+1 -> 4 | ER5: =EQ5+1 -> 5 | ES5: =ER5+1 -> 6 | ET5: =ES5+1 -> 7 | EU5: =ET5+1 -> 8 | ... EX5: =EW5+1 -> 11
B6: Size | C6: ='Inputs & Drivers'!E8 -> 250 | E6: 43465 | F6: 43465 | I6: =C4 -> 43465 | J6: =EOMONTH(I6,1) -> 43496 | K6: =EOMONTH(J6,1) -> 43524 | L6: =EOMONTH(K6,1) -> 43555 | M6: =EOMONTH(L6,1) -> 43585 | N6: =EOMONTH(M6,1) -> 43616 | O6: =EOMONTH(N6,1) -> 43646 | P6: =EOMONTH(O6,1) -> 43677 | Q6: =EOMONTH(P6,1) -> 43708 | ... EK6: =EOMONTH(EJ6,1) -> 47483 | EM6: =I6 -> 43465 | EN6: =EOMONTH(EM6,12) -> 43830 | EO6: =EOMONTH(EN6,12) -> 44196 | EP6: =EOMONTH(EO6,12) -> 44561 | EQ6: =EOMONTH(EP6,12) -> 44926 | ER6: =EOMONTH(EQ6,12) -> 45291 | ES6: =EOMONTH(ER6,12) -> 45657 | ET6: =EOMONTH(ES6,12) -> 46022 | EU6: =EOMONTH(ET6,12) -> 46387 | ... EX6: =EOMONTH(EW6,12) -> 47483
B8: Units Unrenovated | I8: =$C$6-I9 -> 250 | J8: =$C$6-J9 -> 250 | K8: =$C$6-K9 -> 250 | L8: =$C$6-L9 -> 239.58333 | M8: =$C$6-M9 -> 229.16667 | N8: =$C$6-N9 -> 218.75 | O8: =$C$6-O9 -> 208.33333 | P8: =$C$6-P9 -> 197.91667 | ... EK8: =$C$6-EK9 -> 0 | EM8: =SUMIF($I$6:$EK$6,EM$6,$I8:$EK8) -> 250 | EN8: =SUMIF($I$6:$EK$6,EN$6,$I8:$EK8) -> 145.83333 | EO8: =SUMIF($I$6:$EK$6,EO$6,$I8:$EK8) -> 20.833333 | EP8: =SUMIF($I$6:$EK$6,EP$6,$I8:$EK8) -> 0 | EQ8: =SUMIF($I$6:$EK$6,EQ$6,$I8:$EK8) -> 0 | ER8: =SUMIF($I$6:$EK$6,ER$6,$I8:$EK8) -> 0 | ES8: =SUMIF($I$6:$EK$6,ES$6,$I8:$EK8) -> 0 | ET8: =SUMIF($I$6:$EK$6,ET$6,$I8:$EK8) -> 0 | ... EX8: =SUMIF($I$6:$EK$6,EX$6,$I8:$EK8) -> 0
B9: Units Renovated | I9: ='Inputs & Drivers'!E71 -> 0 | J9: =I9+'Inputs & Drivers'!$E$73*(J$6>='Inputs & Drivers'!$C$68)*(J$6<'Inputs & Drivers'!$D$68) -> 0 | K9: =J9+'Inputs & Drivers'!$E$73*(K$6>='Inputs & Drivers'!$C$68)*(K$6<'Inputs & Drivers'!$D$68) -> 0 | L9: =K9+'Inputs & Drivers'!$E$73*(L$6>='Inputs & Drivers'!$C$68)*(L$6<'Inputs & Drivers'!$D$68) -> 10.416667 | M9: =L9+'Inputs & Drivers'!$E$73*(M$6>='Inputs & Drivers'!$C$68)*(M$6<'Inputs & Drivers'!$D$68) -> 20.833333 | N9: =M9+'Inputs & Drivers'!$E$73*(N$6>='Inputs & Drivers'!$C$68)*(N$6<'Inputs & Drivers'!$D$68) -> 31.25 | O9: =N9+'Inputs & Drivers'!$E$73*(O$6>='Inputs & Drivers'!$C$68)*(O$6<'Inputs & Drivers'!$D$68) -> 41.666667 | P9: =O9+'Inputs & Drivers'!$E$73*(P$6>='Inputs & Drivers'!$C$68)*(P$6<'Inputs & Drivers'!$D$68) -> 52.083333 | Q9: =P9+'Inputs & Drivers'!$E$73*(Q$6>='Inputs & Drivers'!$C$68)*(Q$6<'Inputs & Drivers'!$D$68) -> 62.5 | ... EK9: =EJ9+'Inputs & Drivers'!$E$73*(EK$6>='Inputs & Drivers'!$C$68)*(EK$6<'Inputs & Drivers'!$D$68) -> 250 | EM9: =SUMIF($I$6:$EK$6,EM$6,$I9:$EK9) -> 0 | EN9: =SUMIF($I$6:$EK$6,EN$6,$I9:$EK9) -> 104.16667 | EO9: =SUMIF($I$6:$EK$6,EO$6,$I9:$EK9) -> 229.16667 | EP9: =SUMIF($I$6:$EK$6,EP$6,$I9:$EK9) -> 250 | EQ9: =SUMIF($I$6:$EK$6,EQ$6,$I9:$EK9) -> 250 | ER9: =SUMIF($I$6:$EK$6,ER$6,$I9:$EK9) -> 250 | ES9: =SUMIF($I$6:$EK$6,ES$6,$I9:$EK9) -> 250 | ET9: =SUMIF($I$6:$EK$6,ET$6,$I9:$EK9) -> 250 | ... EX9: =SUMIF($I$6:$EK$6,EX$6,$I9:$EK9) -> 250
B10: Unrenovated Effective Rent | I10: ='Inputs & Drivers'!E36 -> 2053.8001 | J10: =I10*(1+J12) -> 2053.8001 | K10: =J10*(1+K12) -> 2053.8001 | L10: =K10*(1+L12) -> 2053.8001 | M10: =L10*(1+M12) -> 2053.8001 | N10: =M10*(1+N12) -> 2053.8001 | O10: =N10*(1+O12) -> 2053.8001 | P10: =O10*(1+P12) -> 2053.8001 | Q10: =P10*(1+Q12) -> 2053.8001 | ... EK10: =EJ10*(1+EK12) -> 2799.0731 | EM10: =SUMIF($I$6:$EK$6,EM$6,$I10:$EK10) -> 2053.8001 | EN10: =SUMIF($I$6:$EK$6,EN$6,$I10:$EK10) -> 2053.8001 | EO10: =SUMIF($I$6:$EK$6,EO$6,$I10:$EK10) -> 2116.2684 | EP10: =SUMIF($I$6:$EK$6,EP$6,$I10:$EK10) -> 2202.4885 | EQ10: =SUMIF($I$6:$EK$6,EQ$6,$I10:$EK10) -> 2269.4793 | ER10: =SUMIF($I$6:$EK$6,ER$6,$I10:$EK10) -> 2338.5076 | ES10: =SUMIF($I$6:$EK$6,ES$6,$I10:$EK10) -> 2409.6356 | ET10: =SUMIF($I$6:$EK$6,ET$6,$I10:$EK10) -> 2482.927 | ... EX10: =SUMIF($I$6:$EK$6,EX$6,$I10:$EK10) -> 2799.0731
B11: Renovated Effective Rent | I11: =I10+'Inputs & Drivers'!$E$74 -> 2178.8001 | J11: =J10+'Inputs & Drivers'!$E$74 -> 2178.8001 | K11: =K10+'Inputs & Drivers'!$E$74 -> 2178.8001 | L11: =L10+'Inputs & Drivers'!$E$74 -> 2178.8001 | M11: =M10+'Inputs & Drivers'!$E$74 -> 2178.8001 | N11: =N10+'Inputs & Drivers'!$E$74 -> 2178.8001 | O11: =O10+'Inputs & Drivers'!$E$74 -> 2178.8001 | P11: =P10+'Inputs & Drivers'!$E$74 -> 2178.8001 | ... EK11: =EK10+'Inputs & Drivers'!$E$74 -> 2924.0731 | EM11: =SUMIF($I$6:$EK$6,EM$6,$I11:$EK11) -> 2178.8001 | EN11: =SUMIF($I$6:$EK$6,EN$6,$I11:$EK11) -> 2178.8001 | EO11: =SUMIF($I$6:$EK$6,EO$6,$I11:$EK11) -> 2241.2684 | EP11: =SUMIF($I$6:$EK$6,EP$6,$I11:$EK11) -> 2327.4885 | EQ11: =SUMIF($I$6:$EK$6,EQ$6,$I11:$EK11) -> 2394.4793 | ER11: =SUMIF($I$6:$EK$6,ER$6,$I11:$EK11) -> 2463.5076 | ES11: =SUMIF($I$6:$EK$6,ES$6,$I11:$EK11) -> 2534.6356 | ET11: =SUMIF($I$6:$EK$6,ET$6,$I11:$EK11) -> 2607.927 | ... EX11: =SUMIF($I$6:$EK$6,EX$6,$I11:$EK11) -> 2924.0731
B12: Rent Growth | J12: =INDEX('Inputs & Drivers'!$E$52:$E$62,MATCH(Model!J$4,'Inputs & Drivers'!$B$52:$B$62,0))/12 -> 0 | K12: =INDEX('Inputs & Drivers'!$E$52:$E$62,MATCH(Model!K$4,'Inputs & Drivers'!$B$52:$B$62,0))/12 -> 0 | L12: =INDEX('Inputs & Drivers'!$E$52:$E$62,MATCH(Model!L$4,'Inputs & Drivers'!$B$52:$B$62,0))/12 -> 0 | M12: =INDEX('Inputs & Drivers'!$E$52:$E$62,MATCH(Model!M$4,'Inputs & Drivers'!$B$52:$B$62,0))/12 -> 0 | N12: =INDEX('Inputs & Drivers'!$E$52:$E$62,MATCH(Model!N$4,'Inputs & Drivers'!$B$52:$B$62,0))/12 -> 0 | O12: =INDEX('Inputs & Drivers'!$E$52:$E$62,MATCH(Model!O$4,'Inputs & Drivers'!$B$52:$B$62,0))/12 -> 0 | P12: =INDEX('Inputs & Drivers'!$E$52:$E$62,MATCH(Model!P$4,'Inputs & Drivers'!$B$52:$B$62,0))/12 -> 0 | Q12: =INDEX('Inputs & Drivers'!$E$52:$E$62,MATCH(Model!Q$4,'Inputs & Drivers'!$B$52:$B$62,0))/12 -> 0 | ... EK12: =INDEX('Inputs & Drivers'!$E$52:$E$62,MATCH(Model!EK$4,'Inputs & Drivers'!$B$52:$B$62,0))/12 -> 0.0025
B14: INCOME
B15: Effective Rent | E15: =SUM('Historical Financials'!M10:O10)*4 -> 6076116.4 | F15: =SUM('Historical Financials'!D10:O10) -> 6161400.4 | J15: =J8*J10+J9*J11 -> 513450.03 | K15: =K8*K10+K9*K11 -> 513450.03 | L15: =L8*L10+L9*L11 -> 514752.12 | M15: =M8*M10+M9*M11 -> 516054.2 | N15: =N8*N10+N9*N11 -> 517356.28 | O15: =O8*O10+O9*O11 -> 518658.37 | P15: =P8*P10+P9*P11 -> 519960.45 | Q15: =Q8*Q10+Q9*Q11 -> 521262.53 | ... EK15: =EK8*EK10+EK9*EK11 -> 731018.29 | EM15: =SUMIF($I$4:$EK$4,EM$5,$I15:$EK15) -> 0 | EN15: =SUMIF($I$4:$EK$4,EN$5,$I15:$EK15) -> 6233015 | EO15: =SUMIF($I$4:$EK$4,EO$5,$I15:$EK15) -> 6520259.2 | EP15: =SUMIF($I$4:$EK$4,EP$5,$I15:$EK15) -> 6861756 | EQ15: =SUMIF($I$4:$EK$4,EQ$5,$I15:$EK15) -> 7090827.1 | ER15: =SUMIF($I$4:$EK$4,ER$5,$I15:$EK15) -> 7295095.5 | ES15: =SUMIF($I$4:$EK$4,ES$5,$I15:$EK15) -> 7505576.8 | ET15: =SUMIF($I$4:$EK$4,ET$5,$I15:$EK15) -> 7722460.1 | ... EX15: =SUMIF($I$4:$EK$4,EX$5,$I15:$EK15) -> 8657997.6
B16: Vacancy Loss | E16: =SUM('Historical Financials'!M15:O15)*4 -> -607611.64 | F16: =SUM('Historical Financials'!D15:O15) -> -616140.04 | J16: =-(1-INDEX('Inputs & Drivers'!$D$52:$D$62,MATCH(Model!J$4,'Inputs & Drivers'!$B$52:$B$62,0)))*J15 -> -46210.503 | K16: =-(1-INDEX('Inputs & Drivers'!$D$52:$D$62,MATCH(Model!K$4,'Inputs & Drivers'!$B$52:$B$62,0)))*K15 -> -46210.503 | L16: =-(1-INDEX('Inputs & Drivers'!$D$52:$D$62,MATCH(Model!L$4,'Inputs & Drivers'!$B$52:$B$62,0)))*L15 -> -46327.69 | M16: =-(1-INDEX('Inputs & Drivers'!$D$52:$D$62,MATCH(Model!M$4,'Inputs & Drivers'!$B$52:$B$62,0)))*M15 -> -46444.878 | N16: =-(1-INDEX('Inputs & Drivers'!$D$52:$D$62,MATCH(Model!N$4,'Inputs & Drivers'!$B$52:$B$62,0)))*N15 -> -46562.065 | O16: =-(1-INDEX('Inputs & Drivers'!$D$52:$D$62,MATCH(Model!O$4,'Inputs & Drivers'!$B$52:$B$62,0)))*O15 -> -46679.253 | P16: =-(1-INDEX('Inputs & Drivers'!$D$52:$D$62,MATCH(Model!P$4,'Inputs & Drivers'!$B$52:$B$62,0)))*P15 -> -46796.44 | Q16: =-(1-INDEX('Inputs & Drivers'!$D$52:$D$62,MATCH(Model!Q$4,'Inputs & Drivers'!$B$52:$B$62,0)))*Q15 -> -46913.628 | ... EK16: =-(1-INDEX('Inputs & Drivers'!$D$52:$D$62,MATCH(Model!EK$4,'Inputs & Drivers'!$B$52:$B$62,0)))*EK15 -> -51171.28 | EM16: =SUMIF($I$4:$EK$4,EM$5,$I16:$EK16) -> 0 | EN16: =SUMIF($I$4:$EK$4,EN$5,$I16:$EK16) -> -560971.35 | EO16: =SUMIF($I$4:$EK$4,EO$5,$I16:$EK16) -> -521620.74 | EP16: =SUMIF($I$4:$EK$4,EP$5,$I16:$EK16) -> -480322.92 | EQ16: =SUMIF($I$4:$EK$4,EQ$5,$I16:$EK16) -> -496357.9 | ER16: =SUMIF($I$4:$EK$4,ER$5,$I16:$EK16) -> -510656.68 | ES16: =SUMIF($I$4:$EK$4,ES$5,$I16:$EK16) -> -525390.37 | ET16: =SUMIF($I$4:$EK$4,ET$5,$I16:$EK16) -> -540572.21 | ... EX16: =SUMIF($I$4:$EK$4,EX$5,$I16:$EK16) -> -606059.84
B17: Non-Revenue Units | E17: =SUM('Historical Financials'!M16:O16)*4 -> 0 | F17: =SUM('Historical Financials'!D16:O16) -> -10560 | J17: =-'Inputs & Drivers'!$D$40*J$15 -> -880 | K17: =-'Inputs & Drivers'!$D$40*K15 -> -880 | L17: =-'Inputs & Drivers'!$D$40*L15 -> -882.23164 | M17: =-'Inputs & Drivers'!$D$40*M15 -> -884.46327 | N17: =-'Inputs & Drivers'!$D$40*N15 -> -886.69491 | O17: =-'Inputs & Drivers'!$D$40*O15 -> -888.92654 | P17: =-'Inputs & Drivers'!$D$40*P15 -> -891.15818 | Q17: =-'Inputs & Drivers'!$D$40*Q15 -> -893.38981 | R17: =-'Inputs & Drivers'!$D$40*R15 -> -895.62145 | ... EK17: =-'Inputs & Drivers'!$D$40*EK15 -> -1252.8894 | EM17: =SUMIF($I$4:$EK$4,EM$5,$I17:$EK17) -> 0 | EN17: =SUMIF($I$4:$EK$4,EN$5,$I17:$EK17) -> -10682.74 | EO17: =SUMIF($I$4:$EK$4,EO$5,$I17:$EK17) -> -11175.047 | EP17: =SUMIF($I$4:$EK$4,EP$5,$I17:$EK17) -> -11760.337 | EQ17: =SUMIF($I$4:$EK$4,EQ$5,$I17:$EK17) -> -12152.941 | ER17: =SUMIF($I$4:$EK$4,ER$5,$I17:$EK17) -> -12503.036 | ES17: =SUMIF($I$4:$EK$4,ES$5,$I17:$EK17) -> -12863.779 | ET17: =SUMIF($I$4:$EK$4,ET$5,$I17:$EK17) -> -13235.494 | ... EX17: =SUMIF($I$4:$EK$4,EX$5,$I17:$EK17) -> -14838.908
B18: Uncollectible Rent | E18: =SUM('Historical Financials'!M17:O17)*4 -> 0 | F18: =SUM('Historical Financials'!D17:O17) -> -24392 | J18: =-'Inputs & Drivers'!$D$41*J$15 -> -2032.6667 | K18: =-'Inputs & Drivers'!$D$41*K$15 -> -2032.6667 | L18: =-'Inputs & Drivers'!$D$41*L$15 -> -2037.8214 | M18: =-'Inputs & Drivers'!$D$41*M$15 -> -2042.9761 | N18: =-'Inputs & Drivers'!$D$41*N$15 -> -2048.1309 | O18: =-'Inputs & Drivers'!$D$41*O$15 -> -2053.2856 | P18: =-'Inputs & Drivers'!$D$41*P$15 -> -2058.4404 | Q18: =-'Inputs & Drivers'!$D$41*Q$15 -> -2063.5951 | ... EK18: =-'Inputs & Drivers'!$D$41*EK$15 -> -2893.9846 | EM18: =SUMIF($I$4:$EK$4,EM$5,$I18:$EK18) -> 0 | EN18: =SUMIF($I$4:$EK$4,EN$5,$I18:$EK18) -> -24675.511 | EO18: =SUMIF($I$4:$EK$4,EO$5,$I18:$EK18) -> -25812.665 | EP18: =SUMIF($I$4:$EK$4,EP$5,$I18:$EK18) -> -27164.596 | EQ18: =SUMIF($I$4:$EK$4,EQ$5,$I18:$EK18) -> -28071.452 | ER18: =SUMIF($I$4:$EK$4,ER$5,$I18:$EK18) -> -28880.118 | ES18: =SUMIF($I$4:$EK$4,ES$5,$I18:$EK18) -> -29713.38 | ET18: =SUMIF($I$4:$EK$4,ET$5,$I18:$EK18) -> -30571.986 | ... EX18: =SUMIF($I$4:$EK$4,EX$5,$I18:$EK18) -> -34275.63
B19: Total Rental Income | E19: =SUM(E15:E18) -> 5468504.8 | F19: =SUM(F15:F18) -> 5510308.4 | J19: =SUM(J15:J18) -> 464326.86 | K19: =SUM(K15:K18) -> 464326.86 | L19: =SUM(L15:L18) -> 465504.37 | M19: =SUM(M15:M18) -> 466681.88 | N19: =SUM(N15:N18) -> 467859.39 | O19: =SUM(O15:O18) -> 469036.9 | P19: =SUM(P15:P18) -> 470214.41 | Q19: =SUM(Q15:Q18) -> 471391.92 | ... EK19: =SUM(EK15:EK18) -> 675700.13 | EM19: =SUM(EM15:EM18) -> 0 | EN19: =SUM(EN15:EN18) -> 5636685.4 | EO19: =SUM(EO15:EO18) -> 5961650.8 | EP19: =SUM(EP15:EP18) -> 6342508.2 | EQ19: =SUM(EQ15:EQ18) -> 6554244.8 | ER19: =SUM(ER15:ER18) -> 6743055.6 | ES19: =SUM(ES15:ES18) -> 6937609.2 | ET19: =SUM(ET15:ET18) -> 7138080.4 | ... EX19: =SUM(EX15:EX18) -> 8002823.3
B20: Effective Rent / Month | E20: =E15/$C$6/12 -> 2025.3721 | F20: =F15/$C$6/12 -> 2053.8001 | J20: =J15/$C$6 -> 2053.8001 | K20: =K15/$C$6 -> 2053.8001 | L20: =L15/$C$6 -> 2059.0085 | M20: =M15/$C$6 -> 2064.2168 | N20: =N15/$C$6 -> 2069.4251 | O20: =O15/$C$6 -> 2074.6335 | P20: =P15/$C$6 -> 2079.8418 | Q20: =Q15/$C$6 -> 2085.0501 | ... EK20: =EK15/$C$6 -> 2924.0731 | EN20: =EN15/$C$6/12 -> 2077.6717 | EO20: =EO15/$C$6/12 -> 2173.4197 | EP20: =EP15/$C$6/12 -> 2287.252 | EQ20: =EQ15/$C$6/12 -> 2363.609 | ER20: =ER15/$C$6/12 -> 2431.6985 | ES20: =ES15/$C$6/12 -> 2501.8589 | ET20: =ET15/$C$6/12 -> 2574.1534 | EU20: =EU15/$C$6/12 -> 2648.6467 | ... EX20: =EX15/$C$6/12 -> 2885.9992
B21: Effective Rent PSF / Month | E21: =E20/'Inputs & Drivers'!$I$10 -> 2.2014914 | F21: =F20/'Inputs & Drivers'!$I$10 -> 2.2323914 | J21: =J20/'Inputs & Drivers'!$I$10 -> 2.2323914 | K21: =K20/'Inputs & Drivers'!$I$10 -> 2.2323914 | L21: =L20/'Inputs & Drivers'!$I$10 -> 2.2380527 | M21: =M20/'Inputs & Drivers'!$I$10 -> 2.2437139 | N21: =N20/'Inputs & Drivers'!$I$10 -> 2.2493751 | O21: =O20/'Inputs & Drivers'!$I$10 -> 2.2550364 | P21: =P20/'Inputs & Drivers'!$I$10 -> 2.2606976 | Q21: =Q20/'Inputs & Drivers'!$I$10 -> 2.2663588 | ... EK21: =EK20/'Inputs & Drivers'!$I$10 -> 3.1783404 | EN21: =EN20/'Inputs & Drivers'!$I$10 -> 2.2583388 | EO21: =EO20/'Inputs & Drivers'!$I$10 -> 2.3624128 | EP21: =EP20/'Inputs & Drivers'!$I$10 -> 2.4861435 | EQ21: =EQ20/'Inputs & Drivers'!$I$10 -> 2.5691403 | ER21: =ER20/'Inputs & Drivers'!$I$10 -> 2.6431505 | ES21: =ES20/'Inputs & Drivers'!$I$10 -> 2.7194119 | ET21: =ET20/'Inputs & Drivers'!$I$10 -> 2.7979928 | EU21: =EU20/'Inputs & Drivers'!$I$10 -> 2.8789638 | ... EX21: =EX20/'Inputs & Drivers'!$I$10 -> 3.1369557
B22: Physical Occupancy | E22: =E16/E15+1 -> 0.9 | F22: =F16/F15+1 -> 0.9 | J22: =J16/J15+1 -> 0.91 | K22: =K16/K15+1 -> 0.91 | L22: =L16/L15+1 -> 0.91 | M22: =M16/M15+1 -> 0.91 | N22: =N16/N15+1 -> 0.91 | O22: =O16/O15+1 -> 0.91 | P22: =P16/P15+1 -> 0.91 | Q22: =Q16/Q15+1 -> 0.91 | ... EK22: =EK16/EK15+1 -> 0.93 | EN22: =EN16/EN15+1 -> 0.91 | EO22: =EO16/EO15+1 -> 0.92 | EP22: =EP16/EP15+1 -> 0.93 | EQ22: =EQ16/EQ15+1 -> 0.93 | ER22: =ER16/ER15+1 -> 0.93 | ES22: =ES16/ES15+1 -> 0.93 | ET22: =ET16/ET15+1 -> 0.93 | EU22: =EU16/EU15+1 -> 0.93 | ... EX22: =EX16/EX15+1 -> 0.93
B23: Economic Occupancy | E23: =E19/E15 -> 0.9 | F23: =F19/F15 -> 0.89432726 | J23: =J19/J15 -> 0.90432726 | K23: =K19/K15 -> 0.90432726 | L23: =L19/L15 -> 0.90432726 | M23: =M19/M15 -> 0.90432726 | N23: =N19/N15 -> 0.90432726 | O23: =O19/O15 -> 0.90432726 | P23: =P19/P15 -> 0.90432726 | Q23: =Q19/Q15 -> 0.90432726 | ... EK23: =EK19/EK15 -> 0.92432726 | EN23: =EN19/EN15 -> 0.90432726 | EO23: =EO19/EO15 -> 0.91432726 | EP23: =EP19/EP15 -> 0.92432726 | EQ23: =EQ19/EQ15 -> 0.92432726 | ER23: =ER19/ER15 -> 0.92432726 | ES23: =ES19/ES15 -> 0.92432726 | ET23: =ET19/ET15 -> 0.92432726 | EU23: =EU19/EU15 -> 0.92432726 | ... EX23: =EX19/EX15 -> 0.92432726
B25: Utility Reimbursement | E25: =SUM('Historical Financials'!M20:O20)*4 -> 106184 | F25: =SUM('Historical Financials'!D20:O20) -> 99715.74 | J25: ='Inputs & Drivers'!E43/12 -> 8309.645 | K25: =(1+INDEX('Inputs & Drivers'!$J$52:$J$62,MATCH(Model!K$4,'Inputs & Drivers'!$B$52:$B$62,0))*(K$4<>J$4))*J25 -> 8309.645 | L25: =(1+INDEX('Inputs & Drivers'!$J$52:$J$62,MATCH(Model!L$4,'Inputs & Drivers'!$B$52:$B$62,0))*(L$4<>K$4))*K25 -> 8309.645 | M25: =(1+INDEX('Inputs & Drivers'!$J$52:$J$62,MATCH(Model!M$4,'Inputs & Drivers'!$B$52:$B$62,0))*(M$4<>L$4))*L25 -> 8309.645 | N25: =(1+INDEX('Inputs & Drivers'!$J$52:$J$62,MATCH(Model!N$4,'Inputs & Drivers'!$B$52:$B$62,0))*(N$4<>M$4))*M25 -> 8309.645 | O25: =(1+INDEX('Inputs & Drivers'!$J$52:$J$62,MATCH(Model!O$4,'Inputs & Drivers'!$B$52:$B$62,0))*(O$4<>N$4))*N25 -> 8309.645 | P25: =(1+INDEX('Inputs & Drivers'!$J$52:$J$62,MATCH(Model!P$4,'Inputs & Drivers'!$B$52:$B$62,0))*(P$4<>O$4))*O25 -> 8309.645 | Q25: =(1+INDEX('Inputs & Drivers'!$J$52:$J$62,MATCH(Model!Q$4,'Inputs & Drivers'!$B$52:$B$62,0))*(Q$4<>P$4))*P25 -> 8309.645 | R25: =(1+INDEX('Inputs & Drivers'!$J$52:$J$62,MATCH(Model!R$4,'Inputs & Drivers'!$B$52:$B$62,0))*(R$4<>Q$4))*Q25 -> 8309.645 | ... EK25: =(1+INDEX('Inputs & Drivers'!$J$52:$J$62,MATCH(Model!EK$4,'Inputs & Drivers'!$B$52:$B$62,0))*(EK$4<>EJ$4))*EJ25 -> 11167.468 | EM25: =SUMIF($I$4:$EK$4,EM$5,$I25:$EK25) -> 0 | EN25: =SUMIF($I$4:$EK$4,EN$5,$I25:$EK25) -> 99715.74 | EO25: =SUMIF($I$4:$EK$4,EO$5,$I25:$EK25) -> 102707.21 | EP25: =SUMIF($I$4:$EK$4,EP$5,$I25:$EK25) -> 105788.43 | EQ25: =SUMIF($I$4:$EK$4,EQ$5,$I25:$EK25) -> 108962.08 | ER25: =SUMIF($I$4:$EK$4,ER$5,$I25:$EK25) -> 112230.94 | ES25: =SUMIF($I$4:$EK$4,ES$5,$I25:$EK25) -> 115597.87 | ET25: =SUMIF($I$4:$EK$4,ET$5,$I25:$EK25) -> 119065.81 | ... EX25: =SUMIF($I$4:$EK$4,EX$5,$I25:$EK25) -> 134009.62
B26: Other Revenue | E26: =SUM('Historical Financials'!M21:O22)*4 -> 271812 | F26: =SUM('Historical Financials'!D21:O22) -> 263945 | J26: ='Inputs & Drivers'!E44/12 -> 21995.417 | K26: =(1+INDEX('Inputs & Drivers'!$J$52:$J$62,MATCH(Model!K$4,'Inputs & Drivers'!$B$52:$B$62,0))*(K$4<>J$4))*J26 -> 21995.417 | L26: =(1+INDEX('Inputs & Drivers'!$J$52:$J$62,MATCH(Model!L$4,'Inputs & Drivers'!$B$52:$B$62,0))*(L$4<>K$4))*K26 -> 21995.417 | M26: =(1+INDEX('Inputs & Drivers'!$J$52:$J$62,MATCH(Model!M$4,'Inputs & Drivers'!$B$52:$B$62,0))*(M$4<>L$4))*L26 -> 21995.417 | N26: =(1+INDEX('Inputs & Drivers'!$J$52:$J$62,MATCH(Model!N$4,'Inputs & Drivers'!$B$52:$B$62,0))*(N$4<>M$4))*M26 -> 21995.417 | O26: =(1+INDEX('Inputs & Drivers'!$J$52:$J$62,MATCH(Model!O$4,'Inputs & Drivers'!$B$52:$B$62,0))*(O$4<>N$4))*N26 -> 21995.417 | P26: =(1+INDEX('Inputs & Drivers'!$J$52:$J$62,MATCH(Model!P$4,'Inputs & Drivers'!$B$52:$B$62,0))*(P$4<>O$4))*O26 -> 21995.417 | Q26: =(1+INDEX('Inputs & Drivers'!$J$52:$J$62,MATCH(Model!Q$4,'Inputs & Drivers'!$B$52:$B$62,0))*(Q$4<>P$4))*P26 -> 21995.417 | R26: =(1+INDEX('Inputs & Drivers'!$J$52:$J$62,MATCH(Model!R$4,'Inputs & Drivers'!$B$52:$B$62,0))*(R$4<>Q$4))*Q26 -> 21995.417 | ... EK26: =(1+INDEX('Inputs & Drivers'!$J$52:$J$62,MATCH(Model!EK$4,'Inputs & Drivers'!$B$52:$B$62,0))*(EK$4<>EJ$4))*EJ26 -> 29560.001 | EM26: =SUMIF($I$4:$EK$4,EM$5,$I26:$EK26) -> 0 | EN26: =SUMIF($I$4:$EK$4,EN$5,$I26:$EK26) -> 263945 | EO26: =SUMIF($I$4:$EK$4,EO$5,$I26:$EK26) -> 271863.35 | EP26: =SUMIF($I$4:$EK$4,EP$5,$I26:$EK26) -> 280019.25 | EQ26: =SUMIF($I$4:$EK$4,EQ$5,$I26:$EK26) -> 288419.83 | ER26: =SUMIF($I$4:$EK$4,ER$5,$I26:$EK26) -> 297072.42 | ES26: =SUMIF($I$4:$EK$4,ES$5,$I26:$EK26) -> 305984.6 | ET26: =SUMIF($I$4:$EK$4,ET$5,$I26:$EK26) -> 315164.13 | ... EX26: =SUMIF($I$4:$EK$4,EX$5,$I26:$EK26) -> 354720.01
B27: Total Other Revenue | E27: =SUM(E25:E26) -> 377996 | F27: =SUM(F25:F26) -> 363660.74 | J27: =SUM(J25:J26) -> 30305.062 | K27: =SUM(K25:K26) -> 30305.062 | L27: =SUM(L25:L26) -> 30305.062 | M27: =SUM(M25:M26) -> 30305.062 | N27: =SUM(N25:N26) -> 30305.062 | O27: =SUM(O25:O26) -> 30305.062 | P27: =SUM(P25:P26) -> 30305.062 | Q27: =SUM(Q25:Q26) -> 30305.062 | ... EK27: =SUM(EK25:EK26) -> 40727.469 | EM27: =SUM(EM25:EM26) -> 0 | EN27: =SUM(EN25:EN26) -> 363660.74 | EO27: =SUM(EO25:EO26) -> 374570.56 | EP27: =SUM(EP25:EP26) -> 385807.68 | EQ27: =SUM(EQ25:EQ26) -> 397381.91 | ER27: =SUM(ER25:ER26) -> 409303.37 | ES27: =SUM(ES25:ES26) -> 421582.47 | ET27: =SUM(ET25:ET26) -> 434229.94 | ... EX27: =SUM(EX25:EX26) -> 488729.63
B29: TOTAL INCOME | E29: =E19+E27 -> 5846500.8 | F29: =F19+F27 -> 5873969.1 | J29: =J19+J27 -> 494631.93 | K29: =K19+K27 -> 494631.93 | L29: =L19+L27 -> 495809.43 | M29: =M19+M27 -> 496986.94 | N29: =N19+N27 -> 498164.45 | O29: =O19+O27 -> 499341.96 | P29: =P19+P27 -> 500519.47 | Q29: =Q19+Q27 -> 501696.98 | ... EK29: =EK19+EK27 -> 716427.6 | EM29: =EM19+EM27 -> 0 | EN29: =EN19+EN27 -> 6000346.1 | EO29: =EO19+EO27 -> 6336221.3 | EP29: =EP19+EP27 -> 6728315.8 | EQ29: =EQ19+EQ27 -> 6951626.8 | ER29: =ER19+ER27 -> 7152359 | ES29: =ES19+ES27 -> 7359191.7 | ET29: =ET19+ET27 -> 7572310.3 | ... EX29: =EX19+EX27 -> 8491552.9
B31: OPERATING EXPENSES | G31: Per Unit
B32: Repairs & Maintenance | E32: =SUM('Historical Financials'!M28:O28)*4 -> -331980 | F32: =SUM('Historical Financials'!D28:O28) -> -294400 | G32: =-E32/$C$6 -> 1327.92 | J32: =-'Inputs & Drivers'!$J35/12 -> -27665 | K32: =(1+INDEX('Inputs & Drivers'!$G$52:$G$62,MATCH(Model!K$4,'Inputs & Drivers'!$B$52:$B$62,0))*(K$4<>J$4))*J32 -> -27665 | L32: =(1+INDEX('Inputs & Drivers'!$G$52:$G$62,MATCH(Model!L$4,'Inputs & Drivers'!$B$52:$B$62,0))*(L$4<>K$4))*K32 -> -27665 | M32: =(1+INDEX('Inputs & Drivers'!$G$52:$G$62,MATCH(Model!M$4,'Inputs & Drivers'!$B$52:$B$62,0))*(M$4<>L$4))*L32 -> -27665 | N32: =(1+INDEX('Inputs & Drivers'!$G$52:$G$62,MATCH(Model!N$4,'Inputs & Drivers'!$B$52:$B$62,0))*(N$4<>M$4))*M32 -> -27665 | O32: =(1+INDEX('Inputs & Drivers'!$G$52:$G$62,MATCH(Model!O$4,'Inputs & Drivers'!$B$52:$B$62,0))*(O$4<>N$4))*N32 -> -27665 | P32: =(1+INDEX('Inputs & Drivers'!$G$52:$G$62,MATCH(Model!P$4,'Inputs & Drivers'!$B$52:$B$62,0))*(P$4<>O$4))*O32 -> -27665 | Q32: =(1+INDEX('Inputs & Drivers'!$G$52:$G$62,MATCH(Model!Q$4,'Inputs & Drivers'!$B$52:$B$62,0))*(Q$4<>P$4))*P32 -> -27665 | R32: =(1+INDEX('Inputs & Drivers'!$G$52:$G$62,MATCH(Model!R$4,'Inputs & Drivers'!$B$52:$B$62,0))*(R$4<>Q$4))*Q32 -> -27665 | ... EK32: =(1+INDEX('Inputs & Drivers'!$G$52:$G$62,MATCH(Model!EK$4,'Inputs & Drivers'!$B$52:$B$62,0))*(EK$4<>EJ$4))*EJ32 -> -37179.447 | EM32: =SUMIF($I$4:$EK$4,EM$5,$I32:$EK32) -> 0 | EN32: =SUMIF($I$4:$EK$4,EN$5,$I32:$EK32) -> -331980 | EO32: =SUMIF($I$4:$EK$4,EO$5,$I32:$EK32) -> -341939.4 | EP32: =SUMIF($I$4:$EK$4,EP$5,$I32:$EK32) -> -352197.58 | EQ32: =SUMIF($I$4:$EK$4,EQ$5,$I32:$EK32) -> -362763.51 | ER32: =SUMIF($I$4:$EK$4,ER$5,$I32:$EK32) -> -373646.41 | ES32: =SUMIF($I$4:$EK$4,ES$5,$I32:$EK32) -> -384855.81 | ET32: =SUMIF($I$4:$EK$4,ET$5,$I32:$EK32) -> -396401.48 | ... EX32: =SUMIF($I$4:$EK$4,EX$5,$I32:$EK32) -> -446153.36
B33: Turnover | E33: =SUM('Historical Financials'!M29:O29)*4 -> -87912 | F33: =SUM('Historical Financials'!D29:O29) -> -74364 | G33: =-E33/$C$6 -> 351.648 | J33: =-'Inputs & Drivers'!$J36/12 -> -7326 | K33: =(1+INDEX('Inputs & Drivers'!$G$52:$G$62,MATCH(Model!K$4,'Inputs & Drivers'!$B$52:$B$62,0))*(K$4<>J$4))*J33 -> -7326 | L33: =(1+INDEX('Inputs & Drivers'!$G$52:$G$62,MATCH(Model!L$4,'Inputs & Drivers'!$B$52:$B$62,0))*(L$4<>K$4))*K33 -> -7326 | M33: =(1+INDEX('Inputs & Drivers'!$G$52:$G$62,MATCH(Model!M$4,'Inputs & Drivers'!$B$52:$B$62,0))*(M$4<>L$4))*L33 -> -7326 | N33: =(1+INDEX('Inputs & Drivers'!$G$52:$G$62,MATCH(Model!N$4,'Inputs & Drivers'!$B$52:$B$62,0))*(N$4<>M$4))*M33 -> -7326 | O33: =(1+INDEX('Inputs & Drivers'!$G$52:$G$62,MATCH(Model!O$4,'Inputs & Drivers'!$B$52:$B$62,0))*(O$4<>N$4))*N33 -> -7326 | P33: =(1+INDEX('Inputs & Drivers'!$G$52:$G$62,MATCH(Model!P$4,'Inputs & Drivers'!$B$52:$B$62,0))*(P$4<>O$4))*O33 -> -7326 | Q33: =(1+INDEX('Inputs & Drivers'!$G$52:$G$62,MATCH(Model!Q$4,'Inputs & Drivers'!$B$52:$B$62,0))*(Q$4<>P$4))*P33 -> -7326 | R33: =(1+INDEX('Inputs & Drivers'!$G$52:$G$62,MATCH(Model!R$4,'Inputs & Drivers'!$B$52:$B$62,0))*(R$4<>Q$4))*Q33 -> -7326 | ... EK33: =(1+INDEX('Inputs & Drivers'!$G$52:$G$62,MATCH(Model!EK$4,'Inputs & Drivers'!$B$52:$B$62,0))*(EK$4<>EJ$4))*EJ33 -> -9845.5314 | EM33: =SUMIF($I$4:$EK$4,EM$5,$I33:$EK33) -> 0 | EN33: =SUMIF($I$4:$EK$4,EN$5,$I33:$EK33) -> -87912 | EO33: =SUMIF($I$4:$EK$4,EO$5,$I33:$EK33) -> -90549.36 | EP33: =SUMIF($I$4:$EK$4,EP$5,$I33:$EK33) -> -93265.841 | EQ33: =SUMIF($I$4:$EK$4,EQ$5,$I33:$EK33) -> -96063.816 | ER33: =SUMIF($I$4:$EK$4,ER$5,$I33:$EK33) -> -98945.731 | ES33: =SUMIF($I$4:$EK$4,ES$5,$I33:$EK33) -> -101914.1 | ET33: =SUMIF($I$4:$EK$4,ET$5,$I33:$EK33) -> -104971.53 | ... EX33: =SUMIF($I$4:$EK$4,EX$5,$I33:$EK33) -> -118146.38
B34: Marketing | E34: =SUM('Historical Financials'!M30:O30)*4 -> -289628 | F34: =SUM('Historical Financials'!D30:O30) -> -183738 | G34: =-E34/$C$6 -> 1158.512 | J34: =-'Inputs & Drivers'!$J37/12 -> -24135.667 | K34: =(1+INDEX('Inputs & Drivers'!$G$52:$G$62,MATCH(Model!K$4,'Inputs & Drivers'!$B$52:$B$62,0))*(K$4<>J$4))*J34 -> -24135.667 | L34: =(1+INDEX('Inputs & Drivers'!$G$52:$G$62,MATCH(Model!L$4,'Inputs & Drivers'!$B$52:$B$62,0))*(L$4<>K$4))*K34 -> -24135.667 | M34: =(1+INDEX('Inputs & Drivers'!$G$52:$G$62,MATCH(Model!M$4,'Inputs & Drivers'!$B$52:$B$62,0))*(M$4<>L$4))*L34 -> -24135.667 | N34: =(1+INDEX('Inputs & Drivers'!$G$52:$G$62,MATCH(Model!N$4,'Inputs & Drivers'!$B$52:$B$62,0))*(N$4<>M$4))*M34 -> -24135.667 | O34: =(1+INDEX('Inputs & Drivers'!$G$52:$G$62,MATCH(Model!O$4,'Inputs & Drivers'!$B$52:$B$62,0))*(O$4<>N$4))*N34 -> -24135.667 | P34: =(1+INDEX('Inputs & Drivers'!$G$52:$G$62,MATCH(Model!P$4,'Inputs & Drivers'!$B$52:$B$62,0))*(P$4<>O$4))*O34 -> -24135.667 | Q34: =(1+INDEX('Inputs & Drivers'!$G$52:$G$62,MATCH(Model!Q$4,'Inputs & Drivers'!$B$52:$B$62,0))*(Q$4<>P$4))*P34 -> -24135.667 | R34: =(1+INDEX('Inputs & Drivers'!$G$52:$G$62,MATCH(Model!R$4,'Inputs & Drivers'!$B$52:$B$62,0))*(R$4<>Q$4))*Q34 -> -24135.667 | ... EK34: =(1+INDEX('Inputs & Drivers'!$G$52:$G$62,MATCH(Model!EK$4,'Inputs & Drivers'!$B$52:$B$62,0))*(EK$4<>EJ$4))*EJ34 -> -32436.318 | EM34: =SUMIF($I$4:$EK$4,EM$5,$I34:$EK34) -> 0 | EN34: =SUMIF($I$4:$EK$4,EN$5,$I34:$EK34) -> -289628 | EO34: =SUMIF($I$4:$EK$4,EO$5,$I34:$EK34) -> -298316.84 | EP34: =SUMIF($I$4:$EK$4,EP$5,$I34:$EK34) -> -307266.35 | EQ34: =SUMIF($I$4:$EK$4,EQ$5,$I34:$EK34) -> -316484.34 | ER34: =SUMIF($I$4:$EK$4,ER$5,$I34:$EK34) -> -325978.87 | ES34: =SUMIF($I$4:$EK$4,ES$5,$I34:$EK34) -> -335758.23 | ET34: =SUMIF($I$4:$EK$4,ET$5,$I34:$EK34) -> -345830.98 | ... EX34: =SUMIF($I$4:$EK$4,EX$5,$I34:$EK34) -> -389235.81
B35: General & Administrative | E35: =SUM('Historical Financials'!M31:O31)*4 -> -70136 | F35: =SUM('Historical Financials'!D31:O31) -> -59547 | G35: =-E35/$C$6 -> 280.544 | J35: =-'Inputs & Drivers'!$J38/12 -> -5844.6667 | K35: =(1+INDEX('Inputs & Drivers'!$G$52:$G$62,MATCH(Model!K$4,'Inputs & Drivers'!$B$52:$B$62,0))*(K$4<>J$4))*J35 -> -5844.6667 | L35: =(1+INDEX('Inputs & Drivers'!$G$52:$G$62,MATCH(Model!L$4,'Inputs & Drivers'!$B$52:$B$62,0))*(L$4<>K$4))*K35 -> -5844.6667 | M35: =(1+INDEX('Inputs & Drivers'!$G$52:$G$62,MATCH(Model!M$4,'Inputs & Drivers'!$B$52:$B$62,0))*(M$4<>L$4))*L35 -> -5844.6667 | N35: =(1+INDEX('Inputs & Drivers'!$G$52:$G$62,MATCH(Model!N$4,'Inputs & Drivers'!$B$52:$B$62,0))*(N$4<>M$4))*M35 -> -5844.6667 | O35: =(1+INDEX('Inputs & Drivers'!$G$52:$G$62,MATCH(Model!O$4,'Inputs & Drivers'!$B$52:$B$62,0))*(O$4<>N$4))*N35 -> -5844.6667 | P35: =(1+INDEX('Inputs & Drivers'!$G$52:$G$62,MATCH(Model!P$4,'Inputs & Drivers'!$B$52:$B$62,0))*(P$4<>O$4))*O35 -> -5844.6667 | Q35: =(1+INDEX('Inputs & Drivers'!$G$52:$G$62,MATCH(Model!Q$4,'Inputs & Drivers'!$B$52:$B$62,0))*(Q$4<>P$4))*P35 -> -5844.6667 | R35: =(1+INDEX('Inputs & Drivers'!$G$52:$G$62,MATCH(Model!R$4,'Inputs & Drivers'!$B$52:$B$62,0))*(R$4<>Q$4))*Q35 -> -5844.6667 | ... EK35: =(1+INDEX('Inputs & Drivers'!$G$52:$G$62,MATCH(Model!EK$4,'Inputs & Drivers'!$B$52:$B$62,0))*(EK$4<>EJ$4))*EJ35 -> -7854.7433 | EM35: =SUMIF($I$4:$EK$4,EM$5,$I35:$EK35) -> 0 | EN35: =SUMIF($I$4:$EK$4,EN$5,$I35:$EK35) -> -70136 | EO35: =SUMIF($I$4:$EK$4,EO$5,$I35:$EK35) -> -72240.08 | EP35: =SUMIF($I$4:$EK$4,EP$5,$I35:$EK35) -> -74407.282 | EQ35: =SUMIF($I$4:$EK$4,EQ$5,$I35:$EK35) -> -76639.501 | ER35: =SUMIF($I$4:$EK$4,ER$5,$I35:$EK35) -> -78938.686 | ES35: =SUMIF($I$4:$EK$4,ES$5,$I35:$EK35) -> -81306.846 | ET35: =SUMIF($I$4:$EK$4,ET$5,$I35:$EK35) -> -83746.052 | ... EX35: =SUMIF($I$4:$EK$4,EX$5,$I35:$EK35) -> -94256.919
B36: Payroll | E36: =SUM('Historical Financials'!M32:O32)*4 -> -379892 | F36: =SUM('Historical Financials'!D32:O32) -> -404335 | G36: =-E36/$C$6 -> 1519.568 | J36: =-'Inputs & Drivers'!$J39/12 -> -31657.667 | K36: =(1+INDEX('Inputs & Drivers'!$G$52:$G$62,MATCH(Model!K$4,'Inputs & Drivers'!$B$52:$B$62,0))*(K$4<>J$4))*J36 -> -31657.667 | L36: =(1+INDEX('Inputs & Drivers'!$G$52:$G$62,MATCH(Model!L$4,'Inputs & Drivers'!$B$52:$B$62,0))*(L$4<>K$4))*K36 -> -31657.667 | M36: =(1+INDEX('Inputs & Drivers'!$G$52:$G$62,MATCH(Model!M$4,'Inputs & Drivers'!$B$52:$B$62,0))*(M$4<>L$4))*L36 -> -31657.667 | N36: =(1+INDEX('Inputs & Drivers'!$G$52:$G$62,MATCH(Model!N$4,'Inputs & Drivers'!$B$52:$B$62,0))*(N$4<>M$4))*M36 -> -31657.667 | O36: =(1+INDEX('Inputs & Drivers'!$G$52:$G$62,MATCH(Model!O$4,'Inputs & Drivers'!$B$52:$B$62,0))*(O$4<>N$4))*N36 -> -31657.667 | P36: =(1+INDEX('Inputs & Drivers'!$G$52:$G$62,MATCH(Model!P$4,'Inputs & Drivers'!$B$52:$B$62,0))*(P$4<>O$4))*O36 -> -31657.667 | Q36: =(1+INDEX('Inputs & Drivers'!$G$52:$G$62,MATCH(Model!Q$4,'Inputs & Drivers'!$B$52:$B$62,0))*(Q$4<>P$4))*P36 -> -31657.667 | R36: =(1+INDEX('Inputs & Drivers'!$G$52:$G$62,MATCH(Model!R$4,'Inputs & Drivers'!$B$52:$B$62,0))*(R$4<>Q$4))*Q36 -> -31657.667 | ... EK36: =(1+INDEX('Inputs & Drivers'!$G$52:$G$62,MATCH(Model!EK$4,'Inputs & Drivers'!$B$52:$B$62,0))*(EK$4<>EJ$4))*EJ36 -> -42545.257 | EM36: =SUMIF($I$4:$EK$4,EM$5,$I36:$EK36) -> 0 | EN36: =SUMIF($I$4:$EK$4,EN$5,$I36:$EK36) -> -379892 | EO36: =SUMIF($I$4:$EK$4,EO$5,$I36:$EK36) -> -391288.76 | EP36: =SUMIF($I$4:$EK$4,EP$5,$I36:$EK36) -> -403027.42 | EQ36: =SUMIF($I$4:$EK$4,EQ$5,$I36:$EK36) -> -415118.25 | ER36: =SUMIF($I$4:$EK$4,ER$5,$I36:$EK36) -> -427571.79 | ES36: =SUMIF($I$4:$EK$4,ES$5,$I36:$EK36) -> -440398.95 | ET36: =SUMIF($I$4:$EK$4,ET$5,$I36:$EK36) -> -453610.92 | ... EX36: =SUMIF($I$4:$EK$4,EX$5,$I36:$EK36) -> -510543.08
B37: Management Fees | E37: =SUM('Historical Financials'!M33:O33)*4 -> -164055.14 | F37: =SUM('Historical Financials'!D33:O33) -> -165309.25 | G37: =-E37/$C$6 -> 656.22057 | J37: =-'Inputs & Drivers'!$H$40*J19 -> -13824.128 | K37: =-'Inputs & Drivers'!$H$40*K19 -> -13824.128 | L37: =-'Inputs & Drivers'!$H$40*L19 -> -13859.186 | M37: =-'Inputs & Drivers'!$H$40*M19 -> -13894.243 | N37: =-'Inputs & Drivers'!$H$40*N19 -> -13929.3 | O37: =-'Inputs & Drivers'!$H$40*O19 -> -13964.357 | P37: =-'Inputs & Drivers'!$H$40*P19 -> -13999.415 | Q37: =-'Inputs & Drivers'!$H$40*Q19 -> -14034.472 | ... EK37: =-'Inputs & Drivers'!$H$40*EK19 -> -20117.219 | EM37: =SUMIF($I$4:$EK$4,EM$5,$I37:$EK37) -> 0 | EN37: =SUMIF($I$4:$EK$4,EN$5,$I37:$EK37) -> -167817.69 | EO37: =SUMIF($I$4:$EK$4,EO$5,$I37:$EK37) -> -177492.69 | EP37: =SUMIF($I$4:$EK$4,EP$5,$I37:$EK37) -> -188831.73 | EQ37: =SUMIF($I$4:$EK$4,EQ$5,$I37:$EK37) -> -195135.64 | ER37: =SUMIF($I$4:$EK$4,ER$5,$I37:$EK37) -> -200757 | ES37: =SUMIF($I$4:$EK$4,ES$5,$I37:$EK37) -> -206549.33 | ET37: =SUMIF($I$4:$EK$4,ET$5,$I37:$EK37) -> -212517.83 | ... EX37: =SUMIF($I$4:$EK$4,EX$5,$I37:$EK37) -> -238263.31
B38: Utilities | E38: =SUM('Historical Financials'!M34:O34)*4 -> -145568 | F38: =SUM('Historical Financials'!D34:O34) -> -149581.28 | G38: =-E38/$C$6 -> 582.272 | J38: =-'Inputs & Drivers'!$J41/12 -> -12130.667 | K38: =(1+INDEX('Inputs & Drivers'!$G$52:$G$62,MATCH(Model!K$4,'Inputs & Drivers'!$B$52:$B$62,0))*(K$4<>J$4))*J38 -> -12130.667 | L38: =(1+INDEX('Inputs & Drivers'!$G$52:$G$62,MATCH(Model!L$4,'Inputs & Drivers'!$B$52:$B$62,0))*(L$4<>K$4))*K38 -> -12130.667 | M38: =(1+INDEX('Inputs & Drivers'!$G$52:$G$62,MATCH(Model!M$4,'Inputs & Drivers'!$B$52:$B$62,0))*(M$4<>L$4))*L38 -> -12130.667 | N38: =(1+INDEX('Inputs & Drivers'!$G$52:$G$62,MATCH(Model!N$4,'Inputs & Drivers'!$B$52:$B$62,0))*(N$4<>M$4))*M38 -> -12130.667 | O38: =(1+INDEX('Inputs & Drivers'!$G$52:$G$62,MATCH(Model!O$4,'Inputs & Drivers'!$B$52:$B$62,0))*(O$4<>N$4))*N38 -> -12130.667 | P38: =(1+INDEX('Inputs & Drivers'!$G$52:$G$62,MATCH(Model!P$4,'Inputs & Drivers'!$B$52:$B$62,0))*(P$4<>O$4))*O38 -> -12130.667 | Q38: =(1+INDEX('Inputs & Drivers'!$G$52:$G$62,MATCH(Model!Q$4,'Inputs & Drivers'!$B$52:$B$62,0))*(Q$4<>P$4))*P38 -> -12130.667 | R38: =(1+INDEX('Inputs & Drivers'!$G$52:$G$62,MATCH(Model!R$4,'Inputs & Drivers'!$B$52:$B$62,0))*(R$4<>Q$4))*Q38 -> -12130.667 | ... EK38: =(1+INDEX('Inputs & Drivers'!$G$52:$G$62,MATCH(Model!EK$4,'Inputs & Drivers'!$B$52:$B$62,0))*(EK$4<>EJ$4))*EJ38 -> -16302.602 | EM38: =SUMIF($I$4:$EK$4,EM$5,$I38:$EK38) -> 0 | EN38: =SUMIF($I$4:$EK$4,EN$5,$I38:$EK38) -> -145568 | EO38: =SUMIF($I$4:$EK$4,EO$5,$I38:$EK38) -> -149935.04 | EP38: =SUMIF($I$4:$EK$4,EP$5,$I38:$EK38) -> -154433.09 | EQ38: =SUMIF($I$4:$EK$4,EQ$5,$I38:$EK38) -> -159066.08 | ER38: =SUMIF($I$4:$EK$4,ER$5,$I38:$EK38) -> -163838.07 | ES38: =SUMIF($I$4:$EK$4,ES$5,$I38:$EK38) -> -168753.21 | ET38: =SUMIF($I$4:$EK$4,ET$5,$I38:$EK38) -> -173815.8 | ... EX38: =SUMIF($I$4:$EK$4,EX$5,$I38:$EK38) -> -195631.22
B39: Real Estate Taxes | E39: =SUM('Historical Financials'!M35:O35)*4 -> -1638504 | F39: =SUM('Historical Financials'!D35:O35) -> -1638504 | G39: =-E39/$C$6 -> 6554.016 | J39: =-'Inputs & Drivers'!$J42/12 -> -136542 | K39: =(1+INDEX('Inputs & Drivers'!$H$52:$H$62,MATCH(Model!K$4,'Inputs & Drivers'!$B$52:$B$62,0))*(K$4<>J$4))*J39 -> -136542 | L39: =(1+INDEX('Inputs & Drivers'!$H$52:$H$62,MATCH(Model!L$4,'Inputs & Drivers'!$B$52:$B$62,0))*(L$4<>K$4))*K39 -> -136542 | M39: =(1+INDEX('Inputs & Drivers'!$H$52:$H$62,MATCH(Model!M$4,'Inputs & Drivers'!$B$52:$B$62,0))*(M$4<>L$4))*L39 -> -136542 | N39: =(1+INDEX('Inputs & Drivers'!$H$52:$H$62,MATCH(Model!N$4,'Inputs & Drivers'!$B$52:$B$62,0))*(N$4<>M$4))*M39 -> -136542 | O39: =(1+INDEX('Inputs & Drivers'!$H$52:$H$62,MATCH(Model!O$4,'Inputs & Drivers'!$B$52:$B$62,0))*(O$4<>N$4))*N39 -> -136542 | P39: =(1+INDEX('Inputs & Drivers'!$H$52:$H$62,MATCH(Model!P$4,'Inputs & Drivers'!$B$52:$B$62,0))*(P$4<>O$4))*O39 -> -136542 | Q39: =(1+INDEX('Inputs & Drivers'!$H$52:$H$62,MATCH(Model!Q$4,'Inputs & Drivers'!$B$52:$B$62,0))*(Q$4<>P$4))*P39 -> -136542 | R39: =(1+INDEX('Inputs & Drivers'!$H$52:$H$62,MATCH(Model!R$4,'Inputs & Drivers'!$B$52:$B$62,0))*(R$4<>Q$4))*Q39 -> -136542 | ... EK39: =(1+INDEX('Inputs & Drivers'!$H$52:$H$62,MATCH(Model!EK$4,'Inputs & Drivers'!$B$52:$B$62,0))*(EK$4<>EJ$4))*EJ39 -> -166443.94 | EM39: =SUMIF($I$4:$EK$4,EM$5,$I39:$EK39) -> 0 | EN39: =SUMIF($I$4:$EK$4,EN$5,$I39:$EK39) -> -1638504 | EO39: =SUMIF($I$4:$EK$4,EO$5,$I39:$EK39) -> -1671274.1 | EP39: =SUMIF($I$4:$EK$4,EP$5,$I39:$EK39) -> -1704699.6 | EQ39: =SUMIF($I$4:$EK$4,EQ$5,$I39:$EK39) -> -1738793.6 | ER39: =SUMIF($I$4:$EK$4,ER$5,$I39:$EK39) -> -1773569.4 | ES39: =SUMIF($I$4:$EK$4,ES$5,$I39:$EK39) -> -1809040.8 | ET39: =SUMIF($I$4:$EK$4,ET$5,$I39:$EK39) -> -1845221.6 | ... EX39: =SUMIF($I$4:$EK$4,EX$5,$I39:$EK39) -> -1997327.2
B40: Property Insurance | E40: =SUM('Historical Financials'!M36:O36)*4 -> -88112 | F40: =SUM('Historical Financials'!D36:O36) -> -83921 | G40: =-E40/$C$6 -> 352.448 | J40: =-'Inputs & Drivers'!$J43/12 -> -7342.6667 | K40: =(1+INDEX('Inputs & Drivers'!$G$52:$G$62,MATCH(Model!K$4,'Inputs & Drivers'!$B$52:$B$62,0))*(K$4<>J$4))*J40 -> -7342.6667 | L40: =(1+INDEX('Inputs & Drivers'!$G$52:$G$62,MATCH(Model!L$4,'Inputs & Drivers'!$B$52:$B$62,0))*(L$4<>K$4))*K40 -> -7342.6667 | M40: =(1+INDEX('Inputs & Drivers'!$G$52:$G$62,MATCH(Model!M$4,'Inputs & Drivers'!$B$52:$B$62,0))*(M$4<>L$4))*L40 -> -7342.6667 | N40: =(1+INDEX('Inputs & Drivers'!$G$52:$G$62,MATCH(Model!N$4,'Inputs & Drivers'!$B$52:$B$62,0))*(N$4<>M$4))*M40 -> -7342.6667 | O40: =(1+INDEX('Inputs & Drivers'!$G$52:$G$62,MATCH(Model!O$4,'Inputs & Drivers'!$B$52:$B$62,0))*(O$4<>N$4))*N40 -> -7342.6667 | P40: =(1+INDEX('Inputs & Drivers'!$G$52:$G$62,MATCH(Model!P$4,'Inputs & Drivers'!$B$52:$B$62,0))*(P$4<>O$4))*O40 -> -7342.6667 | Q40: =(1+INDEX('Inputs & Drivers'!$G$52:$G$62,MATCH(Model!Q$4,'Inputs & Drivers'!$B$52:$B$62,0))*(Q$4<>P$4))*P40 -> -7342.6667 | R40: =(1+INDEX('Inputs & Drivers'!$G$52:$G$62,MATCH(Model!R$4,'Inputs & Drivers'!$B$52:$B$62,0))*(R$4<>Q$4))*Q40 -> -7342.6667 | ... EK40: =(1+INDEX('Inputs & Drivers'!$G$52:$G$62,MATCH(Model!EK$4,'Inputs & Drivers'!$B$52:$B$62,0))*(EK$4<>EJ$4))*EJ40 -> -9867.93 | EM40: =SUMIF($I$4:$EK$4,EM$5,$I40:$EK40) -> 0 | EN40: =SUMIF($I$4:$EK$4,EN$5,$I40:$EK40) -> -88112 | EO40: =SUMIF($I$4:$EK$4,EO$5,$I40:$EK40) -> -90755.36 | EP40: =SUMIF($I$4:$EK$4,EP$5,$I40:$EK40) -> -93478.021 | EQ40: =SUMIF($I$4:$EK$4,EQ$5,$I40:$EK40) -> -96282.361 | ER40: =SUMIF($I$4:$EK$4,ER$5,$I40:$EK40) -> -99170.832 | ES40: =SUMIF($I$4:$EK$4,ES$5,$I40:$EK40) -> -102145.96 | ET40: =SUMIF($I$4:$EK$4,ET$5,$I40:$EK40) -> -105210.34 | ... EX40: =SUMIF($I$4:$EK$4,EX$5,$I40:$EK40) -> -118415.16
B41: Replacement Reserve | E41: 0 | F41: 0 | G41: =-E41/$C$6 -> 0 | J41: =-'Inputs & Drivers'!J45/12 -> -5208.3333 | K41: =J41 -> -5208.3333 | L41: =K41 -> -5208.3333 | M41: =L41 -> -5208.3333 | N41: =M41 -> -5208.3333 | O41: =N41 -> -5208.3333 | P41: =O41 -> -5208.3333 | Q41: =P41 -> -5208.3333 | R41: =Q41 -> -5208.3333 | ... EK41: =EJ41 -> -5208.3333 | EM41: =SUMIF($I$4:$EK$4,EM$5,$I41:$EK41) -> 0 | EN41: =SUMIF($I$4:$EK$4,EN$5,$I41:$EK41) -> -62500 | EO41: =SUMIF($I$4:$EK$4,EO$5,$I41:$EK41) -> -62500 | EP41: =SUMIF($I$4:$EK$4,EP$5,$I41:$EK41) -> -62500 | EQ41: =SUMIF($I$4:$EK$4,EQ$5,$I41:$EK41) -> -62500 | ER41: =SUMIF($I$4:$EK$4,ER$5,$I41:$EK41) -> -62500 | ES41: =SUMIF($I$4:$EK$4,ES$5,$I41:$EK41) -> -62500 | ET41: =SUMIF($I$4:$EK$4,ET$5,$I41:$EK41) -> -62500 | ... EX41: =SUMIF($I$4:$EK$4,EX$5,$I41:$EK41) -> -62500
B42: TOTAL OPERATING EXPENSES | E42: =SUM(E32:E41) -> -3195787.1 | F42: =SUM(F32:F41) -> -3053699.5 | G42: =SUM(G32:G41) -> 12783.149 | J42: =SUM(J32:J41) -> -271676.79 | K42: =SUM(K32:K41) -> -271676.79 | L42: =SUM(L32:L41) -> -271711.85 | M42: =SUM(M32:M41) -> -271746.91 | N42: =SUM(N32:N41) -> -271781.97 | O42: =SUM(O32:O41) -> -271817.02 | P42: =SUM(P32:P41) -> -271852.08 | Q42: =SUM(Q32:Q41) -> -271887.14 | ... EK42: =SUM(EK32:EK41) -> -347801.32 | EM42: =SUM(EM32:EM41) -> 0 | EN42: =SUM(EN32:EN41) -> -3262049.7 | EO42: =SUM(EO32:EO41) -> -3346291.6 | EP42: =SUM(EP32:EP41) -> -3434106.9 | EQ42: =SUM(EQ32:EQ41) -> -3518847.1 | ER42: =SUM(ER32:ER41) -> -3604916.8 | ES42: =SUM(ES32:ES41) -> -3693223.2 | ET42: =SUM(ET32:ET41) -> -3783826.6 | ... EX42: =SUM(EX32:EX41) -> -4170472.5
B44: NET OPERATING INCOME | E44: =E29+E42 -> 2650713.6 | F44: =F29+F42 -> 2820269.6 | J44: =J29+J42 -> 222955.13 | K44: =K29+K42 -> 222955.13 | L44: =L29+L42 -> 224097.58 | M44: =M29+M42 -> 225240.03 | N44: =N29+N42 -> 226382.49 | O44: =O29+O42 -> 227524.94 | P44: =P29+P42 -> 228667.39 | Q44: =Q29+Q42 -> 229809.84 | ... EK44: =EK29+EK42 -> 368626.29 | EM44: =EM29+EM42 -> 0 | EN44: =EN29+EN42 -> 2738296.4 | EO44: =EO29+EO42 -> 2989929.7 | EP44: =EP29+EP42 -> 3294209 | EQ44: =EQ29+EQ42 -> 3432779.7 | ER44: =ER29+ER42 -> 3547442.2 | ES44: =ES29+ES42 -> 3665968.5 | ET44: =ET29+ET42 -> 3788483.8 | ... EX44: =EX29+EX42 -> 4321080.4
B45: Forward 12 Month NOI | J45: =SUM(K44:V44) -> 2751818 | K45: =SUM(L44:W44) -> 2767636.1 | L45: =SUM(M44:X44) -> 2784611.3 | M45: =SUM(N44:Y44) -> 2802746.5 | N45: =SUM(O44:Z44) -> 2822044.4 | O45: =SUM(P44:AA44) -> 2842507.9 | P45: =SUM(Q44:AB44) -> 2864140 | Q45: =SUM(R44:AC44) -> 2886943.5 | ... EK45: =SUM(EL44:EW44) -> 35599505
B46: Margin | E46: =E44/E29 -> 0.45338464 | F46: =F44/F29 -> 0.48013013 | J46: =J44/J29 -> 0.45074958 | K46: =K44/K29 -> 0.45074958 | L46: =L44/L29 -> 0.4519833 | M46: =M44/M29 -> 0.45321117 | N46: =N44/N29 -> 0.45443324 | O46: =O44/O29 -> 0.45564955 | P46: =P44/P29 -> 0.45686013 | Q46: =Q44/Q29 -> 0.45806503 | ... EK46: =EK44/EK29 -> 0.5145339 | EN46: =EN44/EN29 -> 0.45635641 | EO46: =EO44/EO29 -> 0.47187899 | EP46: =EP44/EP29 -> 0.48960379 | EQ46: =EQ44/EQ29 -> 0.49380955 | ER46: =ER44/ER29 -> 0.49598212 | ES46: =ES44/ES29 -> 0.49814825 | ET46: =ET44/ET29 -> 0.50030752 | EU46: =EU44/EU29 -> 0.50245952 | ... EX46: =EX44/EX29 -> 0.5088681
B47: Yield-on-Cost | J47: =(J44*12)/J99 -> 0.051590329 | K47: =(K44*12)/K99 -> 0.051546843 | L47: =(L44*12)/L99 -> 0.051702026 | M47: =(M44*12)/M99 -> 0.051856557 | N47: =(N44*12)/N99 -> 0.052010441 | O47: =(O44*12)/O99 -> 0.052163682 | P47: =(P44*12)/P99 -> 0.052359958 | Q47: =(Q44*12)/Q99 -> 0.052555744 | ... EK47: =(EK44*12)/EK99 -> 0.082445981 | EN47: =EN44/EN99 -> 0.051925845 | EO47: =EO44/EO99 -> 0.055863304 | EP47: =EP44/EP99 -> 0.061397839 | EQ47: =EQ44/EQ99 -> 0.063980536 | ER47: =ER44/ER99 -> 0.066117628 | ES47: =ES44/ES99 -> 0.068326735 | ET47: =ET44/ET99 -> 0.070610189 | EU47: =EU44/EU99 -> 0.072970399 | ... EX47: =EX44/EX99 -> 0.080536786
B49: CAPITAL EXPENDITURES
...

Sheet Historical Financials
B2: 2018 Historical Financials
D4: 43131 | E4: 43159 | F4: 43190 | G4: 43220 | H4: 43251 | I4: 43281 | J4: 43312 | K4: 43343 | L4: 43373 | M4: 43404 | N4: 43434 | O4: 43465
B5: INCOME
B6: Rental Income
B7: Gross Potential Rent | D7: 527980 | E7: 488820 | F7: 499280 | G7: 529495 | H7: 594645 | I7: 513771 | J7: 495575 | K7: 489920 | L7: 485890 | M7: 475795 | N7: 492355 | O7: 497485
B8: Concessions | D8: -2434.3 | E8: -2434.3 | F8: -2434.3 | G8: -2434.3 | H8: -2434.3 | I8: -2434.3 | J8: -2434.3 | K8: -2434.3 | L8: -2434.3 | M8: -2434.3 | N8: -2434.3 | O8: -2434.3
B9: Loss to Lease | D9: -5832 | E9: 31626 | F9: 19193 | G9: -9891 | H9: -71784 | I9: 5533 | J9: 21182 | K9: 23576 | L9: 25301 | M9: 33369 | N9: 16498 | O9: 10830
B10: Effective Rent | D10: 519713.7 | E10: 518011.7 | F10: 516038.7 | G10: 517169.7 | H10: 520426.7 | I10: 516869.7 | J10: 514322.7 | K10: 511061.7 | L10: 508756.7 | M10: 506729.7 | N10: 506418.7 | O10: 505880.7
B11: Effective Rent / Unit | D11: 2078.8548 | E11: 2072.0468 | F11: 2064.1548 | G11: 2068.6788 | H11: 2081.7068 | I11: 2067.4788 | J11: 2057.2908 | K11: 2044.2468 | L11: 2035.0268 | M11: 2026.9188 | N11: 2025.6748 | O11: 2023.5228
B12: Effective Rent / SF | D12: 2.2596248 | E12: 2.2522248 | F12: 2.2436465 | G12: 2.2485639 | H12: 2.2627248 | I12: 2.2472596 | J12: 2.2361857 | K12: 2.2220074 | L12: 2.2119857 | M12: 2.2031726 | N12: 2.2018204 | O12: 2.1994813
B13: Occupancy | D13: 0.9 | E13: 0.9 | F13: 0.9 | G13: 0.9 | H13: 0.9 | I13: 0.9 | J13: 0.9 | K13: 0.9 | L13: 0.9 | M13: 0.9 | N13: 0.9 | O13: 0.9
B15: Vacancy Loss | D15: -51971.37 | E15: -51801.17 | F15: -51603.87 | G15: -51716.97 | H15: -52042.67 | I15: -51686.97 | J15: -51432.27 | K15: -51106.17 | L15: -50875.67 | M15: -50672.97 | N15: -50641.87 | O15: -50588.07
