Workbook
Name IQ_CH: 110000
Name IQ_CQ: 5000
Name IQ_CY: 10000
Name IQ_DAILY: 500000
Name IQ_FH: 100000
Name IQ_FQ: 500
Name IQ_FY: 1000
Name IQ_LTM: 2000
Name IQ_MONTH: 15000
Name IQ_NTM: 6000
Name IQ_WEEK: 50000
Name IQ_YTD: 3000

Sheet FSM Data Input
C2: ="Financial Statement Model for "&D5 -> Financial Statement Model for Apple
C3: $ in thousands except per share
C5: Company name | D5: Apple
C6: Ticker | D6: AAPL
C7: Circ break 1=off, 0=on | D7: 1
C8: Latest closing share price | D8: 171.25
C9: Latest closing share price date | D9: 43500
C10: Latest fiscal year end date | D10: 43372
C11: Shares outstanding (millions) | D11: 4745.398
C13: INCOME STATEMENT
C14: Fiscal year | D14: =E14-1 -> 2016 | E14: =F14-1 -> 2017 | F14: =YEAR(D10) -> 2018
C15: Fiscal year end date | D15: =EOMONTH(E15,-12) -> 42643 | E15: =EOMONTH(F15,-12) -> 43008 | F15: =D10 -> 43372
C17: Revenue | D17: 215639 | E17: 229234 | F17: 265595
C18: Cost of sales (enter as -) | D18: -131376 | E18: -141048 | F18: -163756
C19: Gross Profit | D19: =SUM(D17:D18) -> 84263 | E19: =SUM(E17:E18) -> 88186 | F19: =SUM(F17:F18) -> 101839
C20: Research & development (enter as -) | D20: -10045 | E20: -11581 | F20: -14236
C21: Selling, general & administrative (enter as -) | D21: -14194 | E21: -15261 | F21: -16705
C22: Operating profit (EBIT) | D22: =SUM(D19:D21) -> 60024 | E22: =SUM(E19:E21) -> 61344 | F22: =SUM(F19:F21) -> 70898
C23: Interest income | D23: 3999 | E23: 5201 | F23: 5686
C24: Interest expense (enter as -) | D24: -1456 | E24: -2323 | F24: -3240
C25: Other expense, net (enter as -) | D25: -1195 | E25: -133 | F25: -441
C26: Pretax profit | D26: =SUM(D22:D25) -> 61372 | E26: =SUM(E22:E25) -> 64089 | F26: =SUM(F22:F25) -> 72903
C27: Taxes (enter expense as -) | D27: -15685 | E27: -15738 | F27: -13372
C28: Net income | D28: =SUM(D26:D27) -> 45687 | E28: =SUM(E26:E27) -> 48351 | F28: =SUM(F26:F27) -> 59531
C30: Depreciation & amortization | D30: 10505 | E30: 10157 | F30: 10903 | H30: From cash flow statement
C31: EBITDA | D31: =D22+D30 -> 70529 | E31: =E22+E30 -> 71501 | F31: =F22+F30 -> 81801 | H31: EBIT + D&A
C32: Stock based compensation | D32: 4210 | E32: 4840 | F32: 5340 | H32: From cash flow statement
C33: Adjusted EBITDA | D33: =SUM(D31:D32) -> 74739 | E33: =SUM(E31:E32) -> 76341 | F33: =SUM(F31:F32) -> 87141 | H33: EBITDA + Stock-based compensation
C35: Growth rates & margins
C36: Revenue growth | E36: =E17/D17-1 -> 0.063045182 | F36: =F17/E17-1 -> 0.15861958 | H36: Current year / Last year - 1
C37: Gross profit margin | D37: =D19/D17 -> 0.39075956 | E37: =E19/E17 -> 0.3846986 | F37: =F19/F17 -> 0.38343719 | H37: Gross profit / revenue
C38: R&D % of sales | D38: =-(D20/D17) -> 0.046582483 | E38: =-(E20/E17) -> 0.050520429 | F38: =-(F20/F17) -> 0.053600407 | H38: R&D / Revenue
C39: SG&A % of sales | D39: =-(D21/D17) -> 0.065822973 | E39: =-(E21/E17) -> 0.066573894 | F39: =-(F21/F17) -> 0.062896515 | H39: SG&A / Revenue
C40: Tax rate | D40: =-(D27/D26) -> 0.25557257 | E40: =-(E27/E26) -> 0.24556476 | F40: =-(F27/F26) -> 0.18342181 | H40: Taxes / Pretax Profit
C42: BALANCE SHEET
C43: =C14 -> Fiscal year | E43: =E14 -> 2017 | F43: =F14 -> 2018
C44: =C15 -> Fiscal year end date | E44: =E15 -> 43008 | F44: =F15 -> 43372
C45: Cash & equivalents, ST and LT marketable securities | E45: =20289+53892+194714 -> 268895 | F45: =25913+40388+170799 -> 237100
C46: Accounts receivable | E46: 17874 | F46: 23186
C47: Inventories | E47: 4855 | F47: 3956
...

Sheet FSM
C2: ="Financial Statement Model for "&D5 -> Financial Statement Model for Apple
C3: $ in thousands except per share
C5: Company name | D5: Apple
C6: Ticker | D6: AAPL
C7: Circ break 1=off, 0=on | D7: 1
C8: Latest closing share price | D8: 171.25
C9: Latest closing share price date | D9: 43500
C10: Latest fiscal year end date | D10: 43372
C11: Shares outstanding (millions) | D11: 4745.398
C13: INCOME STATEMENT
C14: Fiscal year | D14: =E14-1 -> 2016 | E14: =F14-1 -> 2017 | F14: =YEAR(D10) -> 2018 | G14: =F14+1 -> 2019 | H14: =G14+1 -> 2020 | I14: =H14+1 -> 2021 | J14: =I14+1 -> 2022 | K14: =J14+1 -> 2023
C15: Fiscal year end date | D15: =EOMONTH(E15,-12) -> 42643 | E15: =EOMONTH(F15,-12) -> 43008 | F15: =D10 -> 43372 | G15: =EOMONTH(F15,12) -> 43738 | H15: =EOMONTH(G15,12) -> 44104 | I15: =EOMONTH(H15,12) -> 44469 | J15: =EOMONTH(I15,12) -> 44834 | K15: =EOMONTH(J15,12) -> 45199
C17: Revenue | D17: 215639 | E17: 229234 | F17: 265595 | G17: =F17*(1+G36) -> 254971.2 | H17: =G17*(1+H36) -> 270269.47 | I17: =H17*(1+I36) -> 288918.07 | J17: =I17*(1+J36) -> 308853.41 | K17: =J17*(1+K36) -> 330164.3 | M17: Previous year's revenues x (1+revenue growth rate)
C18: Cost of sales (enter as -) | D18: -131376 | E18: -141048 | F18: -163756 | G18: =G19-G17 -> -158592.09 | H18: =H19-H17 -> -167296.8 | I18: =I19-I17 -> -178551.36 | J18: =J19-J17 -> -190871.41 | K18: =K19-K17 -> -204041.54 | M18: Plug = Revenue - Gross Profit
C19: Gross Profit | D19: =SUM(D17:D18) -> 84263 | E19: =SUM(E17:E18) -> 88186 | F19: =SUM(F17:F18) -> 101839 | G19: =G17*G37 -> 96379.114 | H19: =H17*H37 -> 102972.67 | I19: =I17*I37 -> 110366.7 | J19: =J17*J37 -> 117982 | K19: =K17*K37 -> 126122.76 | M19: Revenue x Gross Profit Margin forecast
C20: Research & development (enter as -) | D20: -10045 | E20: -11581 | F20: -14236 | G20: =-G38*G17 -> -15808.214 | H20: =-H38*H17 -> -17026.977 | I20: =-I38*I17 -> -18201.838 | J20: =-J38*J17 -> -19457.765 | K20: =-K38*K17 -> -20800.351 | M20: Revenue x R&D % of sales forecast
C21: Selling, general & administrative (enter as -) | D21: -14194 | E21: -15261 | F21: -16705 | G21: =-G17*G39 -> -18867.869 | H21: =-H17*H39 -> -18648.594 | I21: =-I17*I39 -> -19935.347 | J21: =-J17*J39 -> -21310.885 | K21: =-K17*K39 -> -22781.337 | M21: Revenue x SG&A % of sales forecast
C22: Operating profit (EBIT) | D22: =D19+D20+D21 -> 60024 | E22: =E19+E20+E21 -> 61344 | F22: =F19+F20+F21 -> 70898 | G22: =G19+G20+G21 -> 61703.03 | H22: =H19+H20+H21 -> 67297.099 | I22: =I19+I20+I21 -> 72229.516 | J22: =J19+J20+J21 -> 77213.353 | K22: =K19+K20+K21 -> 82541.074 | M22: Gross Profit - R&D - SG&A
C23: Interest income | D23: 3999 | E23: 5201 | F23: 5686 | G23: =G156 -> 4744.4371 | H23: =H156 -> 4090.2133 | I23: =I156 -> 3592.0871 | J23: =J156 -> 3200.5876 | K23: =K156 -> 2913.2593 | M23: Reference from interest on cash schedule
C24: Interest expense (enter as -) | D24: -1456 | E24: -2323 | F24: -3240 | G24: =-G142 -> -3223.1469 | H24: =-H142 -> -3223.5393 | I24: =-I142 -> -3223.5393 | J24: =-J142 -> -3223.5393 | K24: =-K142 -> -3223.5393 | M24: Reference from interest expense schedule
C25: Other expense, net (enter as -) | D25: -1195 | E25: -133 | F25: -441 | G25: =F25 -> -441 | H25: =G25 -> -441 | I25: =H25 -> -441 | J25: =I25 -> -441 | K25: =J25 -> -441 | M25: Straight-line
C26: Pretax profit | D26: =SUM(D22:D25) -> 61372 | E26: =SUM(E22:E25) -> 64089 | F26: =SUM(F22:F25) -> 72903 | G26: =SUM(G22:G25) -> 62783.321 | H26: =SUM(H22:H25) -> 67722.773 | I26: =SUM(I22:I25) -> 72157.064 | J26: =SUM(J22:J25) -> 76749.401 | K26: =SUM(K22:K25) -> 81789.794 | M26: EBIT + interest income less interest expense less other expense
C27: Taxes (enter expense as -) | D27: -15685 | E27: -15738 | F27: -13372 | G27: =-G40*G26 -> -10484.815 | H27: =-H40*H26 -> -11512.871 | I27: =-I40*I26 -> -12194.544 | J27: =-J40*J26 -> -12970.649 | K27: =-K40*K26 -> -13822.475 | M27: Pre-tax Profit x Tax Rate forecast
C28: Net income | D28: =SUM(D26:D27) -> 45687 | E28: =SUM(E26:E27) -> 48351 | F28: =SUM(F26:F27) -> 59531 | G28: =SUM(G26:G27) -> 52298.506 | H28: =SUM(H26:H27) -> 56209.901 | I28: =SUM(I26:I27) -> 59962.52 | J28: =SUM(J26:J27) -> 63778.753 | K28: =SUM(K26:K27) -> 67967.319 | M28: Pre-tax Profit less taxes
C30: Depreciation & amortization | D30: 10505 | E30: 10157 | F30: 10903 | G30: =G106 -> 11085.02 | H30: =H106 -> 11711.891 | I30: =I106 -> 12226.381 | J30: =J106 -> 13365.451 | K30: =K106 -> 14603.503 | M30: Reference from D&A schedule
C31: EBITDA | D31: =D22+D30 -> 70529 | E31: =E22+E30 -> 71501 | F31: =F22+F30 -> 81801 | G31: =G22+G30 -> 72788.051 | H31: =H22+H30 -> 79008.989 | I31: =I22+I30 -> 84455.897 | J31: =J22+J30 -> 90578.804 | K31: =K22+K30 -> 97144.578 | M31: EBIT + D&A
C32: Stock based compensation | D32: 4210 | E32: 4840 | F32: 5340 | G32: =F32*(1+G36) -> 5126.4 | H32: =G32*(1+H36) -> 5433.984 | I32: =H32*(1+I36) -> 5808.9289 | J32: =I32*(1+J36) -> 6209.745 | K32: =J32*(1+K36) -> 6638.2174 | M32: WSP assumption: grow SBC in-line with revenue growth
C33: Adjusted EBITDA | D33: =SUM(D31:D32) -> 74739 | E33: =SUM(E31:E32) -> 76341 | F33: =SUM(F31:F32) -> 87141 | G33: =SUM(G31:G32) -> 77914.451 | H33: =SUM(H31:H32) -> 84442.973 | I33: =SUM(I31:I32) -> 90264.826 | J33: =SUM(J31:J32) -> 96788.549 | K33: =SUM(K31:K32) -> 103782.8 | M33: EBITDA + Stock-based compensation
C35: Growth rates & margins
C36: Revenue growth | E36: =E17/D17-1 -> 0.063045182 | F36: =F17/E17-1 -> 0.15861958 | G36: -0.04 | H36: 0.06 | I36: 0.069 | J36: =I36 -> 0.069 | K36: =J36 -> 0.069 | M36: JP Morgan estimates through 2021; straight-line growth rate thereafter
C37: Gross profit margin | D37: =D19/D17 -> 0.39075956 | E37: =E19/E17 -> 0.3846986 | F37: =F19/F17 -> 0.38343719 | G37: 0.378 | H37: 0.381 | I37: 0.382 | J37: =I37 -> 0.382 | K37: =J37 -> 0.382 | M37: JP Morgan estimates through 2021; straight-line margin thereafter
C38: R&D % of sales | D38: =-D20/D17 -> 0.046582483 | E38: =-E20/E17 -> 0.050520429 | F38: =-F20/F17 -> 0.053600407 | G38: 0.062 | H38: 0.063 | I38: 0.063 | J38: =I38 -> 0.063 | K38: =J38 -> 0.063 | M38: JP Morgan estimates through 2021: straight-line margin thereafter
C39: SG&A % of sales | D39: =-D21/D17 -> 0.065822973 | E39: =-E21/E17 -> 0.066573894 | F39: =-F21/F17 -> 0.062896515 | G39: 0.074 | H39: 0.069 | I39: 0.069 | J39: =I39 -> 0.069 | K39: =J39 -> 0.069 | M39: JP Morgan estimates through 2021: straight-line margin thereafter
C40: Tax rate | D40: =-(D27/D26) -> 0.25557257 | E40: =-(E27/E26) -> 0.24556476 | F40: =-(F27/F26) -> 0.18342181 | G40: 0.167 | H40: 0.17 | I40: 0.169 | J40: =I40 -> 0.169 | K40: =J40 -> 0.169 | M40: JP Morgan estimates through 2021: straight-line margin thereafter
C42: BALANCE SHEET
C43: =C14 -> Fiscal year | E43: =E14 -> 2017 | F43: =F14 -> 2018 | G43: =G14 -> 2019 | H43: =H14 -> 2020 | I43: =I14 -> 2021 | J43: =J14 -> 2022 | K43: =K14 -> 2023
C44: =C15 -> Fiscal year end date | E44: =E15 -> 43008 | F44: =F15 -> 43372 | G44: =G15 -> 43738 | H44: =H15 -> 44104 | I44: =I15 -> 44469 | J44: =J15 -> 44834 | K44: =K15 -> 45199
C45: Cash & equivalents, ST and LT marketable securities | E45: =20289+53892+194714 -> 268895 | F45: =25913+40388+170799 -> 237100 | G45: =G90+F45 -> 202199.73 | H45: =H90+G45 -> 176523.72 | I45: =I90+H45 -> 156076.93 | J45: =J90+I45 -> 140273.78 | K45: =K90+J45 -> 129472.46 | M45: Reference from 'net change in cash' line on the cash flow statement
C46: Accounts receivable | E46: 17874 | F46: 23186 | G46: =F46*(1+G36) -> 22258.56 | H46: =G46*(1+H36) -> 23594.074 | I46: =H46*(1+I36) -> 25222.065 | J46: =I46*(1+J36) -> 26962.387 | K46: =J46*(1+K36) -> 28822.792 | M46: Grow in-line with revenue growth
C47: Inventories | E47: 4855 | F47: 3956 | G47: =F47*G18/F18 -> 3831.2507 | H47: =G47*H18/G18 -> 4041.5383 | I47: =H47*I18/H18 -> 4313.4248 | J47: =I47*J18/I18 -> 4611.0512 | K47: =J47*K18/J18 -> 4929.2137 | M47: Grow in-line with cost of sales growth
...

Sheet Extras
C2: ="Financial Statement Model for "&D5 -> Financial Statement Model for Apple
C3: $ in thousands except per share
C5: Company name | D5: Apple
C6: Ticker | D6: AAPL
C7: Circ break 1=off, 0=on | D7: 1
C8: Latest closing share price | D8: 171.25
C9: Latest closing share price date | D9: 43500
C10: Latest fiscal year end date | D10: 43372
C11: Shares outstanding (millions) | D11: 4745.398
C12: Select an operating scenario: | D12: Base case
C14: INCOME STATEMENT
C15: Fiscal year | D15: =E15-1 -> 2016 | E15: =F15-1 -> 2017 | F15: =YEAR(D10) -> 2018 | G15: =F15+1 -> 2019 | H15: =G15+1 -> 2020 | I15: =H15+1 -> 2021 | J15: =I15+1 -> 2022 | K15: =J15+1 -> 2023
C16: Fiscal year end date | D16: =EOMONTH(E16,-12) -> 42643 | E16: =EOMONTH(F16,-12) -> 43008 | F16: =D10 -> 43372 | G16: =EOMONTH(F16,12) -> 43738 | H16: =EOMONTH(G16,12) -> 44104 | I16: =EOMONTH(H16,12) -> 44469 | J16: =EOMONTH(I16,12) -> 44834 | K16: =EOMONTH(J16,12) -> 45199
C18: Revenue | D18: 215639 | E18: 229234 | F18: 265595 | G18: =F18*(1+G37) -> 254971.2 | H18: =G18*(1+H37) -> 270269.47 | I18: =H18*(1+I37) -> 288918.07 | J18: =I18*(1+J37) -> 308853.41 | K18: =J18*(1+K37) -> 330164.3 | M18: Previous year's revenues x (1+revenue growth rate)
C19: Cost of sales (enter as -) | D19: -131376 | E19: -141048 | F19: -163756 | G19: =G20-G18 -> -158592.09 | H19: =H20-H18 -> -167296.8 | I19: =I20-I18 -> -178551.36 | J19: =J20-J18 -> -190871.41 | K19: =K20-K18 -> -204041.54 | M19: Plug = Revenue - Gross Profit
C20: Gross Profit | D20: =SUM(D18:D19) -> 84263 | E20: =SUM(E18:E19) -> 88186 | F20: =SUM(F18:F19) -> 101839 | G20: =G18*G38 -> 96379.114 | H20: =H18*H38 -> 102972.67 | I20: =I18*I38 -> 110366.7 | J20: =J18*J38 -> 117982 | K20: =K18*K38 -> 126122.76 | M20: Revenue x Gross Profit Margin forecast
C21: Research & development (enter as -) | D21: -10045 | E21: -11581 | F21: -14236 | G21: =-G39*G18 -> -15808.214 | H21: =-H39*H18 -> -17026.977 | I21: =-I39*I18 -> -18201.838 | J21: =-J39*J18 -> -19457.765 | K21: =-K39*K18 -> -20800.351 | M21: Revenue x R&D % of sales forecast
C22: Selling, general & administrative (enter as -) | D22: -14194 | E22: -15261 | F22: -16705 | G22: =-G18*G40 -> -18867.869 | H22: =-H18*H40 -> -18648.594 | I22: =-I18*I40 -> -19935.347 | J22: =-J18*J40 -> -21310.885 | K22: =-K18*K40 -> -22781.337 | M22: Revenue x SG&A % of sales forecast
C23: Operating profit (EBIT) | D23: =D20+D21+D22 -> 60024 | E23: =E20+E21+E22 -> 61344 | F23: =F20+F21+F22 -> 70898 | G23: =G20+G21+G22 -> 61703.03 | H23: =H20+H21+H22 -> 67297.099 | I23: =I20+I21+I22 -> 72229.516 | J23: =J20+J21+J22 -> 77213.353 | K23: =K20+K21+K22 -> 82541.074 | M23: Gross Profit - R&D - SG&A
C24: Interest income | D24: 3999 | E24: 5201 | F24: 5686 | G24: =G157 -> 4744.4371 | H24: =H157 -> 4090.2133 | I24: =I157 -> 3592.0871 | J24: =J157 -> 3200.5876 | K24: =K157 -> 2913.2593 | M24: Reference from interest on cash schedule
C25: Interest expense (enter as -) | D25: -1456 | E25: -2323 | F25: -3240 | G25: =-G143 -> -3223.1469 | H25: =-H143 -> -3223.5393 | I25: =-I143 -> -3223.5393 | J25: =-J143 -> -3223.5393 | K25: =-K143 -> -3223.5393 | M25: Reference from interest expense schedule
C26: Other expense, net (enter as -) | D26: -1195 | E26: -133 | F26: -441 | G26: =F26 -> -441 | H26: =G26 -> -441 | I26: =H26 -> -441 | J26: =I26 -> -441 | K26: =J26 -> -441 | M26: Straight-line
C27: Pretax profit | D27: =SUM(D23:D26) -> 61372 | E27: =SUM(E23:E26) -> 64089 | F27: =SUM(F23:F26) -> 72903 | G27: =SUM(G23:G26) -> 62783.321 | H27: =SUM(H23:H26) -> 67722.773 | I27: =SUM(I23:I26) -> 72157.064 | J27: =SUM(J23:J26) -> 76749.401 | K27: =SUM(K23:K26) -> 81789.794 | M27: EBIT + interest income less interest expense less other expense
C28: Taxes (enter expense as -) | D28: -15685 | E28: -15738 | F28: -13372 | G28: =-G41*G27 -> -10484.815 | H28: =-H41*H27 -> -11512.871 | I28: =-I41*I27 -> -12194.544 | J28: =-J41*J27 -> -12970.649 | K28: =-K41*K27 -> -13822.475 | M28: Pre-tax Profit x Tax Rate forecast
C29: Net income | D29: =SUM(D27:D28) -> 45687 | E29: =SUM(E27:E28) -> 48351 | F29: =SUM(F27:F28) -> 59531 | G29: =SUM(G27:G28) -> 52298.506 | H29: =SUM(H27:H28) -> 56209.901 | I29: =SUM(I27:I28) -> 59962.52 | J29: =SUM(J27:J28) -> 63778.753 | K29: =SUM(K27:K28) -> 67967.319 | M29: Pre-tax Profit less taxes
C31: Depreciation & amortization | D31: 10505 | E31: 10157 | F31: 10903 | G31: =G107 -> 11085.02 | H31: =H107 -> 11711.891 | I31: =I107 -> 12226.381 | J31: =J107 -> 13365.451 | K31: =K107 -> 14603.503 | M31: Reference from D&A schedule
C32: EBITDA | D32: =D23+D31 -> 70529 | E32: =E23+E31 -> 71501 | F32: =F23+F31 -> 81801 | G32: =G23+G31 -> 72788.051 | H32: =H23+H31 -> 79008.989 | I32: =I23+I31 -> 84455.897 | J32: =J23+J31 -> 90578.804 | K32: =K23+K31 -> 97144.578 | M32: EBIT + D&A
C33: Stock based compensation | D33: 4210 | E33: 4840 | F33: 5340 | G33: =F33*(1+G37) -> 5126.4 | H33: =G33*(1+H37) -> 5433.984 | I33: =H33*(1+I37) -> 5808.9289 | J33: =I33*(1+J37) -> 6209.745 | K33: =J33*(1+K37) -> 6638.2174 | M33: WSP assumption: grow SBC in-line with revenue growth
C34: Adjusted EBITDA | D34: =SUM(D32:D33) -> 74739 | E34: =SUM(E32:E33) -> 76341 | F34: =SUM(F32:F33) -> 87141 | G34: =SUM(G32:G33) -> 77914.451 | H34: =SUM(H32:H33) -> 84442.973 | I34: =SUM(I32:I33) -> 90264.826 | J34: =SUM(J32:J33) -> 96788.549 | K34: =SUM(K32:K33) -> 103782.8 | M34: EBITDA + Stock-based compensation
C36: Growth rates & margins
C37: Revenue growth | E37: =E18/D18-1 -> 0.063045182 | F37: =F18/E18-1 -> 0.15861958 | G37: =G175 -> -0.04 | H37: =H175 -> 0.06 | I37: =I175 -> 0.069 | J37: =J175 -> 0.069 | K37: =K175 -> 0.069 | M37: From scenario analysis below
C38: Gross profit margin | D38: =D20/D18 -> 0.39075956 | E38: =E20/E18 -> 0.3846986 | F38: =F20/F18 -> 0.38343719 | G38: =G176 -> 0.378 | H38: =H176 -> 0.381 | I38: =I176 -> 0.382 | J38: =J176 -> 0.382 | K38: =K176 -> 0.382 | M38: From scenario analysis below
C39: R&D % of sales | D39: =-D21/D18 -> 0.046582483 | E39: =-E21/E18 -> 0.050520429 | F39: =-F21/F18 -> 0.053600407 | G39: =G177 -> 0.062 | H39: =H177 -> 0.063 | I39: =I177 -> 0.063 | J39: =J177 -> 0.063 | K39: =K177 -> 0.063 | M39: From scenario analysis below
C40: SG&A % of sales | D40: =-D22/D18 -> 0.065822973 | E40: =-E22/E18 -> 0.066573894 | F40: =-F22/F18 -> 0.062896515 | G40: =G178 -> 0.074 | H40: =H178 -> 0.069 | I40: =I178 -> 0.069 | J40: =J178 -> 0.069 | K40: =K178 -> 0.069 | M40: From scenario analysis below
C41: Tax rate | D41: =-(D28/D27) -> 0.25557257 | E41: =-(E28/E27) -> 0.24556476 | F41: =-(F28/F27) -> 0.18342181 | G41: 0.167 | H41: 0.17 | I41: 0.169 | J41: =I41 -> 0.169 | K41: =J41 -> 0.169 | M41: JP Morgan estimates through 2021: straight-line margin thereafter
C43: BALANCE SHEET
C44: =C15 -> Fiscal year | E44: =E15 -> 2017 | F44: =F15 -> 2018 | G44: =G15 -> 2019 | H44: =H15 -> 2020 | I44: =I15 -> 2021 | J44: =J15 -> 2022 | K44: =K15 -> 2023
C45: =C16 -> Fiscal year end date | E45: =E16 -> 43008 | F45: =F16 -> 43372 | G45: =G16 -> 43738 | H45: =H16 -> 44104 | I45: =I16 -> 44469 | J45: =J16 -> 44834 | K45: =K16 -> 45199
C46: Cash & equivalents, ST and LT marketable securities | E46: =20289+53892+194714 -> 268895 | F46: =25913+40388+170799 -> 237100 | G46: =G91+F46 -> 202199.73 | H46: =H91+G46 -> 176523.72 | I46: =I91+H46 -> 156076.93 | J46: =J91+I46 -> 140273.78 | K46: =K91+J46 -> 129472.46 | M46: Reference from 'net change in cash' line on the cash flow statement
C47: Accounts receivable | E47: 17874 | F47: 23186 | G47: =F47*(1+G37) -> 22258.56 | H47: =G47*(1+H37) -> 23594.074 | I47: =H47*(1+I37) -> 25222.065 | J47: =I47*(1+J37) -> 26962.387 | K47: =J47*(1+K37) -> 28822.792 | M47: Grow in-line with revenue growth
...

Sheet Rev Build
C2: Price / volume build
C3: =Extras!C15 -> Fiscal year | D3: =Extras!D15 -> 2016 | E3: =Extras!E15 -> 2017 | F3: =Extras!F15 -> 2018 | G3: =Extras!G15 -> 2019 | H3: =Extras!H15 -> 2020 | I3: =Extras!I15 -> 2021 | J3: =Extras!J15 -> 2022 | K3: =Extras!K15 -> 2023
C4: =Extras!C16 -> Fiscal year end date | D4: =Extras!D16 -> 42643 | E4: =Extras!E16 -> 43008 | F4: =Extras!F16 -> 43372 | G4: =Extras!G16 -> 43738 | H4: =Extras!H16 -> 44104 | I4: =Extras!I16 -> 44469 | J4: =Extras!J16 -> 44834 | K4: =Extras!K16 -> 45199
C5: Revenue by product
C6: Core products
C7: iPhone | D7: 136700 | E7: 141319 | F7: 166699 | G7: =G17*G22/1000 -> 137570.4 | H7: =H17*H22/1000 -> 138388 | I7: =I17*I22/1000 -> 138388 | J7: =J17*J22/1000 -> 138388 | K7: =K17*K22/1000 -> 138388
C8: iPad | D8: 20628 | E8: 19222 | F8: 18805 | G8: =G18*G23/1000 -> 20222.922 | H8: =H18*H23/1000 -> 20475.904 | I8: =I18*I23/1000 -> 20475.904 | J8: =J18*J23/1000 -> 20475.904 | K8: =K18*K23/1000 -> 20475.904
C9: Mac | D9: 22831 | E9: 25850 | F9: 25484 | G9: =G19*G24/1000 -> 26515.16 | H9: =H19*H24/1000 -> 26642.88 | I9: =I19*I24/1000 -> 26642.88 | J9: =J19*J24/1000 -> 26642.88 | K9: =K19*K24/1000 -> 26642.88
C11: Services | D11: 24348 | E11: 29980 | F11: 37190 | G11: 45603 | H11: 53592 | I11: =H11*(1+I40) -> 62980.56 | J11: =I11*(1+J40) -> 74013.862 | K11: =J11*(1+K40) -> 86980.043 | M11: CG estimates through 2020; WSP thereafter based on growth rate assumption
C12: Other products | D12: 11132 | E12: 12863 | F12: 17417 | G12: 23079 | H12: 26278 | I12: =H12*(1+I41) -> 29920.416 | J12: =I12*(1+J41) -> 34067.711 | K12: =J12*(1+K41) -> 38789.865 | M12: CG estimates through 2020; WSP thereafter based on growth rate assumption
C13: Total revenue | D13: =SUM(D7:D9)+SUM(D11:D12) -> 215639 | E13: =SUM(E7:E9)+SUM(E11:E12) -> 229234 | F13: =SUM(F7:F9)+SUM(F11:F12) -> 265595 | G13: =SUM(G7:G9)+SUM(G11:G12) -> 252990.48 | H13: =SUM(H7:H9)+SUM(H11:H12) -> 265376.78 | I13: =SUM(I7:I9)+SUM(I11:I12) -> 278407.76 | J13: =SUM(J7:J9)+SUM(J11:J12) -> 293588.36 | K13: =SUM(K7:K9)+SUM(K11:K12) -> 311276.69
C14: % growth | E14: =E13/D13-1 -> 0.063045182 | F14: =F13/E13-1 -> 0.15861958 | G14: =G13/F13-1 -> -0.047457664 | H14: =H13/G13-1 -> 0.048959559 | I14: =I13/H13-1 -> 0.049103677 | J14: =J13/I13-1 -> 0.054526487 | K14: =K13/J13-1 -> 0.060248763
C16: Units
C17: iPhone | D17: 211884 | E17: 216756 | F17: 217722 | G17: 173700 | H17: 190880 | I17: 190880 | J17: 190880 | K17: 190880 | M17: CG estimates through 2020; Straight line therafter
C18: iPad | D18: 45590 | E18: 43753 | F18: 43535 | G18: 46170 | H18: 49260 | I18: 49260 | J18: 49260 | K18: 49260 | M18: CG estimates through 2020; Straight line therafter
C19: Mac | D19: 18484 | E19: 19251 | F19: 18209 | G19: 19670 | H19: 19140 | I19: 19140 | J19: 19140 | K19: 19140 | M19: CG estimates through 2020; Straight line therafter
C21: Average selling price
C22: iPhone | D22: =D7/D17*1000 -> 645.16434 | E22: =E7/E17*1000 -> 651.97273 | F22: =F7/F17*1000 -> 765.65069 | G22: 792 | H22: 725 | I22: 725 | J22: 725 | K22: 725 | M22: CG estimates through 2020; Straight line therafter
C23: iPad | D23: =D8/D18*1000 -> 452.46765 | E23: =E8/E18*1000 -> 439.32987 | F23: =F8/F18*1000 -> 431.9513 | G23: 438.01 | H23: 415.67 | I23: 415.67 | J23: 415.67 | K23: 415.67 | M23: CG estimates through 2020; Straight line therafter
C24: Mac | D24: =D9/D19*1000 -> 1235.1764 | E24: =E9/E19*1000 -> 1342.7874 | F24: =F9/F19*1000 -> 1399.5277 | G24: 1348 | H24: 1392 | I24: 1392 | J24: 1392 | K24: 1392 | M24: CG estimates through 2020; Straight line therafter
C26: Units % growth
C27: iPhone | E27: =E17/D17-1 -> 0.022993714 | F27: =F17/E17-1 -> 0.004456624 | G27: =G17/F17-1 -> -0.20219362 | H27: =H17/G17-1 -> 0.09890616 | I27: =I17/H17-1 -> 0 | J27: =J17/I17-1 -> 0 | K27: =K17/J17-1 -> 0
C28: iPad | E28: =E18/D18-1 -> -0.040293924 | F28: =F18/E18-1 -> -0.0049825155 | G28: =G18/F18-1 -> 0.060526014 | H28: =H18/G18-1 -> 0.066926576 | I28: =I18/H18-1 -> 0 | J28: =J18/I18-1 -> 0 | K28: =K18/J18-1 -> 0
C29: Mac | E29: =E19/D19-1 -> 0.041495347 | F29: =F19/E19-1 -> -0.054127058 | G29: =G19/F19-1 -> 0.080235049 | H29: =H19/G19-1 -> -0.026944586 | I29: =I19/H19-1 -> 0 | J29: =J19/I19-1 -> 0 | K29: =K19/J19-1 -> 0
C31: Average selling price % growth
C32: iPhone | E32: =E22/D22-1 -> 0.010552955 | F32: =F22/E22-1 -> 0.17436 | G32: =G22/F22-1 -> 0.034414268 | H32: =H22/G22-1 -> -0.08459596 | I32: =I22/H22-1 -> 0 | J32: =J22/I22-1 -> 0 | K32: =K22/J22-1 -> 0
C33: iPad | E33: =E23/D23-1 -> -0.029035826 | F33: =F23/E23-1 -> -0.016795059 | G33: =G23/F23-1 -> 0.014026341 | H33: =H23/G23-1 -> -0.051003402 | I33: =I23/H23-1 -> 0 | J33: =J23/I23-1 -> 0 | K33: =K23/J23-1 -> 0
C34: Mac | E34: =E24/D24-1 -> 0.087121986 | F34: =F24/E24-1 -> 0.042255624 | G34: =G24/F24-1 -> -0.036817925 | H34: =H24/G24-1 -> 0.03264095 | I34: =I24/H24-1 -> 0 | J34: =J24/I24-1 -> 0 | K34: =K24/J24-1 -> 0
C36: Revenue growth rate by product
C37: iPhone | E37: =E7/D7-1 -> 0.03378932 | F37: =F7/E7-1 -> 0.17959369 | G37: =G7/F7-1 -> -0.1747377 | H37: =H7/G7-1 -> 0.0059431389 | I37: =I7/H7-1 -> 0 | J37: =J7/I7-1 -> 0 | K37: =K7/J7-1 -> 0
C38: iPad | E38: =E8/D8-1 -> -0.068159783 | F38: =F8/E8-1 -> -0.021693892 | G38: =G8/F8-1 -> 0.075401313 | H38: =H8/G8-1 -> 0.012509691 | I38: =I8/H8-1 -> 0 | J38: =J8/I8-1 -> 0 | K38: =K8/J8-1 -> 0
C39: Mac | E39: =E9/D9-1 -> 0.13223249 | F39: =F9/E9-1 -> -0.014158607 | G39: =G9/F9-1 -> 0.040463036 | H39: =H9/G9-1 -> 0.004816867 | I39: =I9/H9-1 -> 0 | J39: =J9/I9-1 -> 0 | K39: =K9/J9-1 -> 0
C40: Services | E40: =E11/D11-1 -> 0.23131263 | F40: =F11/E11-1 -> 0.24049366 | G40: =G11/F11-1 -> 0.22621672 | H40: =H11/G11-1 -> 0.17518584 | I40: =H40 -> 0.17518584 | J40: =I40 -> 0.17518584 | K40: =J40 -> 0.17518584 | M40: CG estimates through 2020; Straight line growth rate thereafter
C41: Other products | E41: =E12/D12-1 -> 0.15549766 | F41: =F12/E12-1 -> 0.35403872 | G41: =G12/F12-1 -> 0.32508469 | H41: =H12/G12-1 -> 0.13861086 | I41: =H41 -> 0.13861086 | J41: =I41 -> 0.13861086 | K41: =J41 -> 0.13861086 | M41: CG estimates through 2020; Straight line growth rate thereafter
M43: "iPhone ASP will be primary driver as Apple continues to increase hardware prices."
M44: Jeffries research note January 30, 2019

Sheet 2019 FSM Update
C2: ="Financial Statement Model for "&D5 -> Financial Statement Model for Apple
C3: $ in thousands except per share
C5: Company name | D5: Apple | I5: Select an operating scenario: | L5: Base case
C6: Ticker | D6: AAPL
C7: Circ break 1=off, 0=on | D7: 1
C8: Latest closing share price | D8: 293.65
C9: Latest closing share price date | D9: 43830
C10: Latest fiscal year end date | D10: 43737
C11: Shares outstanding (millions) | D11: 4443.265
C13: INCOME STATEMENT
C14: Fiscal year | D14: =E14-1 -> 2016 | E14: =F14-1 -> 2017 | F14: =G14-1 -> 2018 | G14: =YEAR(D10) -> 2019 | H14: =G14+1 -> 2020 | I14: =H14+1 -> 2021 | J14: =I14+1 -> 2022 | K14: =J14+1 -> 2023 | L14: =K14+1 -> 2024
C15: Fiscal year end date | D15: =EOMONTH(E15,-12) -> 42643 | E15: =EOMONTH(F15,-12) -> 43008 | F15: 43372 | G15: =D10 -> 43737 | H15: =EOMONTH(G15,12) -> 44104 | I15: =EOMONTH(H15,12) -> 44469 | J15: =EOMONTH(I15,12) -> 44834 | K15: =EOMONTH(J15,12) -> 45199 | L15: =EOMONTH(K15,12) -> 45565
C17: Revenue | D17: 215639 | E17: 229234 | F17: 265595 | G17: 260174 | H17: =G17*(1+H36) -> 275784.44 | I17: =H17*(1+I36) -> 294813.57 | J17: =I17*(1+J36) -> 315155.7 | K17: =J17*(1+K36) -> 336901.45 | L17: =K17*(1+L36) -> 360147.65 | N17: Previous year's revenues x (1+revenue growth rate)
C18: Cost of sales (enter as -) | D18: -131376 | E18: -141048 | F18: -163756 | G18: -161782 | H18: =H19-H17 -> -171537.92 | I18: =I19-I17 -> -183374.04 | J18: =J19-J17 -> -196026.85 | K18: =K19-K17 -> -209552.7 | L18: =L19-L17 -> -224011.84 | N18: Plug = Revenue - Gross Profit
C19: Gross Profit | D19: =SUM(D17:D18) -> 84263 | E19: =SUM(E17:E18) -> 88186 | F19: =SUM(F17:F18) -> 101839 | G19: =SUM(G17:G18) -> 98392 | H19: =H17*H37 -> 104246.52 | I19: =I17*I37 -> 111439.53 | J19: =J17*J37 -> 119128.86 | K19: =K17*K37 -> 127348.75 | L19: =L17*L37 -> 136135.81 | N19: Revenue x Gross Profit Margin forecast
C20: Research & development (enter as -) | D20: -10045 | E20: -11581 | F20: -14236 | G20: -16217 | H20: =-H38*H17 -> -17098.635 | I20: =-I38*I17 -> -18278.441 | J20: =-J38*J17 -> -19539.654 | K20: =-K38*K17 -> -20887.89 | L20: =-L38*L17 -> -22329.154 | N20: Revenue x R&D % of sales forecast
C21: Selling, general & administrative (enter as -) | D21: -14194 | E21: -15261 | F21: -16705 | G21: -18245 | H21: =-H17*H39 -> -19304.911 | I21: =-I17*I39 -> -20636.95 | J21: =-J17*J39 -> -22060.899 | K21: =-K17*K39 -> -23583.101 | L21: =-L17*L39 -> -25210.335 | N21: Revenue x SG&A % of sales forecast
C22: Operating profit (EBIT) | D22: =D19+D20+D21 -> 60024 | E22: =E19+E20+E21 -> 61344 | F22: =F19+F20+F21 -> 70898 | G22: =G19+G20+G21 -> 63930 | H22: =H19+H20+H21 -> 67842.972 | I22: =I19+I20+I21 -> 72524.137 | J22: =J19+J20+J21 -> 77528.303 | K22: =K19+K20+K21 -> 82877.756 | L22: =L19+L20+L21 -> 88596.321 | N22: Gross Profit - R&D - SG&A
C23: Interest income | D23: 3999 | E23: 5201 | F23: 5686 | G23: 4961 | H23: =H156 -> 4386.8466 | I23: =I156 -> 4119.4834 | J23: =J156 -> 3871.0562 | K23: =K156 -> 3709.7511 | L23: =L156 -> 3643.4637 | N23: Reference from interest on cash schedule
C24: Interest expense (enter as -) | D24: -1456 | E24: -2323 | F24: -3240 | G24: -3576 | H24: =-H142 -> -3568.9466 | I24: =-I142 -> -3636.3706 | J24: =-J142 -> -3636.3706 | K24: =-K142 -> -3636.3706 | L24: =-L142 -> -3636.3706 | N24: Reference from interest expense schedule
C25: Other expense, net (enter as -) | D25: -1195 | E25: -133 | F25: -441 | G25: 422 | H25: =G25 -> 422 | I25: =H25 -> 422 | J25: =I25 -> 422 | K25: =J25 -> 422 | L25: =K25 -> 422 | N25: Straight-line
C26: Pretax profit | D26: =SUM(D22:D25) -> 61372 | E26: =SUM(E22:E25) -> 64089 | F26: =SUM(F22:F25) -> 72903 | G26: =SUM(G22:G25) -> 65737 | H26: =SUM(H22:H25) -> 69082.872 | I26: =SUM(I22:I25) -> 73429.25 | J26: =SUM(J22:J25) -> 78184.988 | K26: =SUM(K22:K25) -> 83373.136 | L26: =SUM(L22:L25) -> 89025.414 | N26: EBIT + interest income less interest expense less other expense
C27: Taxes (enter expense as -) | D27: -15685 | E27: -15738 | F27: -13372 | G27: -10481 | H27: =-H40*H26 -> -11014.46 | I27: =-I40*I26 -> -11707.44 | J27: =-J40*J26 -> -12465.687 | K27: =-K40*K26 -> -13292.877 | L27: =-L40*L26 -> -14194.067 | N27: Pre-tax Profit x Tax Rate forecast
C28: Net income | D28: =SUM(D26:D27) -> 45687 | E28: =SUM(E26:E27) -> 48351 | F28: =SUM(F26:F27) -> 59531 | G28: =SUM(G26:G27) -> 55256 | H28: =SUM(H26:H27) -> 58068.412 | I28: =SUM(I26:I27) -> 61721.81 | J28: =SUM(J26:J27) -> 65719.301 | K28: =SUM(K26:K27) -> 70080.259 | L28: =SUM(L26:L27) -> 74831.347 | N28: Pre-tax Profit less taxes
C30: Depreciation & amortization | D30: 10505 | E30: 10157 | F30: 10903 | G30: 12547 | H30: =H106 -> 11808.331 | I30: =I106 -> 12418.253 | J30: =J106 -> 13558.159 | K30: =K106 -> 14796.249 | L30: =L106 -> 16140.644 | N30: Reference from D&A schedule
C31: EBITDA | D31: =D22+D30 -> 70529 | E31: =E22+E30 -> 71501 | F31: =F22+F30 -> 81801 | G31: =G22+G30 -> 76477 | H31: =H22+H30 -> 79651.303 | I31: =I22+I30 -> 84942.391 | J31: =J22+J30 -> 91086.462 | K31: =K22+K30 -> 97674.004 | L31: =L22+L30 -> 104736.97 | N31: EBIT + D&A
C32: Stock based compensation | D32: 4210 | E32: 4840 | F32: 5340 | G32: 6068 | H32: =G32*(1+H36) -> 6432.08 | I32: =H32*(1+I36) -> 6875.8935 | J32: =I32*(1+J36) -> 7350.3302 | K32: =J32*(1+K36) -> 7857.503 | L32: =K32*(1+L36) -> 8399.6707 | N32: WSP assumption: grow SBC in-line with revenue growth
C33: Adjusted EBITDA | D33: =SUM(D31:D32) -> 74739 | E33: =SUM(E31:E32) -> 76341 | F33: =SUM(F31:F32) -> 87141 | G33: =SUM(G31:G32) -> 82545 | H33: =SUM(H31:H32) -> 86083.383 | I33: =SUM(I31:I32) -> 91818.284 | J33: =SUM(J31:J32) -> 98436.792 | K33: =SUM(K31:K32) -> 105531.51 | L33: =SUM(L31:L32) -> 113136.64 | N33: EBITDA + Stock-based compensation
C35: Growth rates & margins
C36: Revenue growth | E36: =E17/D17-1 -> 0.063045182 | F36: =F17/E17-1 -> 0.15861958 | G36: =G17/F17-1 -> -0.020410776 | H36: =H183 -> 0.06 | I36: =I183 -> 0.069 | J36: =J183 -> 0.069 | K36: =K183 -> 0.069 | L36: =L183 -> 0.069 | N36: Consensus estimates through 2021; straight-line growth rate thereafter
C37: Gross profit margin | D37: =D19/D17 -> 0.39075956 | E37: =E19/E17 -> 0.3846986 | F37: =F19/F17 -> 0.38343719 | G37: =G19/G17 -> 0.37817768 | H37: =H184 -> 0.378 | I37: =I184 -> 0.378 | J37: =J184 -> 0.378 | K37: =K184 -> 0.378 | L37: =L184 -> 0.378 | N37: Straight line last historical year
C38: R&D % of sales | D38: =-D20/D17 -> 0.046582483 | E38: =-E20/E17 -> 0.050520429 | F38: =-F20/F17 -> 0.053600407 | G38: =-G20/G17 -> 0.062331363 | H38: =H185 -> 0.062 | I38: =I185 -> 0.062 | J38: =J185 -> 0.062 | K38: =K185 -> 0.062 | L38: =L185 -> 0.062 | N38: Straight line last historical year
C39: SG&A % of sales | D39: =-D21/D17 -> 0.065822973 | E39: =-E21/E17 -> 0.066573894 | F39: =-F21/F17 -> 0.062896515 | G39: =-G21/G17 -> 0.070126146 | H39: =H186 -> 0.07 | I39: =I186 -> 0.07 | J39: =J186 -> 0.07 | K39: =K186 -> 0.07 | L39: =L186 -> 0.07 | N39: Straight line last historical year
C40: Tax rate | D40: =-(D27/D26) -> 0.25557257 | E40: =-(E27/E26) -> 0.24556476 | F40: =-(F27/F26) -> 0.18342181 | G40: =-(G27/G26) -> 0.15943837 | H40: =G40 -> 0.15943837 | I40: =H40 -> 0.15943837 | J40: =I40 -> 0.15943837 | K40: =J40 -> 0.15943837 | L40: =K40 -> 0.15943837 | N40: Straight line last historical year
C42: BALANCE SHEET
C43: =C14 -> Fiscal year | E43: =E14 -> 2017 | F43: =F14 -> 2018 | G43: =G14 -> 2019 | H43: =H14 -> 2020 | I43: =I14 -> 2021 | J43: =J14 -> 2022 | K43: =K14 -> 2023 | L43: =L14 -> 2024
C44: =C15 -> Fiscal year end date | E44: =E15 -> 43008 | F44: =F15 -> 43372 | G44: =G15 -> 43737 | H44: =H15 -> 44104 | I44: =I15 -> 44469 | J44: =J15 -> 44834 | K44: =K15 -> 45199 | L44: =L15 -> 45565
C45: Cash & equivalents, ST and LT marketable securities | E45: =20289+53892+194714 -> 268895 | F45: =25913+40388+170799 -> 237100 | G45: =48844+51713+105341 -> 205898 | H45: =H90+G45 -> 194727.26 | I45: =I90+H45 -> 181481.27 | J45: =J90+I45 -> 172039.84 | K45: =K90+J45 -> 166750.22 | L45: =L90+K45 -> 165986.19 | N45: Reference from 'net change in cash' line on the cash flow statement
C46: Accounts receivable | E46: 17874 | F46: 23186 | G46: 22926 | H46: =G46*(1+H36) -> 24301.56 | I46: =H46*(1+I36) -> 25978.368 | J46: =I46*(1+J36) -> 27770.875 | K46: =J46*(1+K36) -> 29687.065 | L46: =K46*(1+L36) -> 31735.473 | N46: Grow in-line with revenue growth
C47: Inventories | E47: 4855 | F47: 3956 | G47: 4106 | H47: =G47*H18/G18 -> 4353.6037 | I47: =H47*I18/H18 -> 4654.0023 | J47: =I47*J18/I18 -> 4975.1285 | K47: =J47*K18/J18 -> 5318.4123 | L47: =K47*L18/K18 -> 5685.3828 | N47: Grow in-line with cost of sales growth
...
